Workbook
Name CPWD_Carriage_Item_Codes: '01_Carriage_of_Materials'!$A$180:$A$216
Name CPWD_Carriage_Materials: '01_Carriage_of_Materials'!$B$180:$B$216
Name CPWD_Carriage_Net_Payable: '01_Carriage_of_Materials'!$D$180:$D$216
Name CPWD_Carriage_Scope: '01_Carriage_of_Materials'!$A$260:$A$265
Name CPWD_Carriage12_Materials: '01_Carriage_of_Materials'!$B$221:$B$255
Name CPWD_Carriage14_Items: '01_Carriage_of_Materials'!$A$269:$A$272
Name CPWD_Carriage14_Table: '01_Carriage_of_Materials'!$A$269:$M$272
Name CPWD_DataSheet1: '01_Carriage_of_Materials'!$A$146:$H$175
Name CPWD_Earth_Items: '02_Earth_Work'!$P$100:$P$148
Name Factor_Cess: Global_Factors!$F$15
Name Factor_CPOH: Global_Factors!$F$14
Name Factor_GST: Global_Factors!$F$13
Name Factor_Sundries: Global_Factors!$F$16
Name Factor_Water: Global_Factors!$F$12
Name Master_Codes: Rates_Master!$A$2:$A$2142
Name Master_Rates_Table: Rates_Master!$A$2:$E$2142
Name Productivity_Summary: Labour_Machinery_Productivity!$A$6:$L$179
Name Productivity_Work_Types: Labour_Machinery_Productivity!$A$6:$A$179
Name Resolved_Cess_Factor: IF(Global_Factors!$E$15<>"",Global_Factors!$E$15,Global_Factors!$C$15)
Name Resolved_CPOH_Factor: IF(Global_Factors!$E$14<>"",Global_Factors!$E$14,Global_Factors!$C$14)
Name Resolved_GST_Factor: IF(Global_Factors!$E$13<>"",Global_Factors!$E$13,Global_Factors!$C$13)
Name Resolved_Water_Factor: IF(Global_Factors!$E$12<>"",Global_Factors!$E$12,Global_Factors!$C$12)
Name Table_5E_Master: '02_Earth_Work'!$P$100:$V$148
Name Table_5E_Resources: '02_Earth_Work'!$A$100:$O$277
Name Total_Active_Rates: COUNTA(Rates_Master!$A:$A)-1
Name Total_Labour_Norms: COUNTA(Labour_Machinery_Productivity!$C$183:$C$3206)
Name Total_Sundries_Norms: COUNTA(Sundries_Reference!$A:$A)-1
Name Total_Work_Type_Crews: ROWS(Labour_Machinery_Productivity!$A$6:$A$179)
Name XV_13_50_1: Resolved_Cross_Volume_Items!$G$66
Name XV_13_50_3: Resolved_Cross_Volume_Items!$G$86
Name XV_13_57_1: Resolved_Cross_Volume_Items!$G$107
Name XV_18_78: Resolved_Cross_Volume_Items!$G$126
Name XV_4_2_5: Resolved_Cross_Volume_Items!$G$44

Sheet Vol_1_Cover
A1: CPWD DAR 2019 | CUSTOM RATE ANALYSIS WORKBOOK — VOLUME 1 (Sub-Heads 01–12) Template File | Open → Work → Save As <Project Name>.xlsx | Do NOT rename this file
A3: ★ TEMPLATE — THIS FILE OPENS FRESH EACH TIME ★ Nothing you type here is saved to the template. To keep your work: File → Save As → give it a project/item name (e.g. "ItemAnalysis_CC_Flooring.xlsx").
A7: HOW TO USE THIS WORKBOOK 1. SHEET LAYOUT (each trade sheet 01–12 has the same structure): Panel 1 — Scope & Item Identification (yellow INPUT cells) Section 2 — Material Block (enter code → rate auto-fills from Rates_Master) Section 3 — Labour Block (same lookup pattern) Section 4 — Sundries, Markup Chain, Say Rate 2. YELLOW CELLS are user inputs. All other cells are calculated — do not overtype them. 3. RATES_MASTER: 2,200 CPWD DAR 2019 codes with basic rates. Type the code in Column B of the material/labour block; description, unit and rate fill automatically. To override a rate, type it directly in Column F of that row. 4. GLOBAL FACTORS (Water Tax, GST, CPOH, Cess, Sundries%) are in the Global_Factors sheet. Change them there once; all trade sheets update automatically. 5. IF YOU USE VOL. 2 (Sub-Heads 13–26): Before opening Vol. 2, save THIS file as: CPWD_DAR_2019_Custom_Rate_Analysis_Workbook_Vol_1.xlsx in the SAME FOLDER as Vol. 2. Vol. 2 external links depend on that exact filename. 6. REFERENCE SHEETS (read-only): Rates_Master, Global_Factors, Labour_Machinery_Productivity, Sundries_Reference, Resolved_Cross_Volume_Items — do not edit these; regenerate from source if needed.

Sheet Rates_Master
A1: Code | B1: Category | C1: Description / Specification | D1: Unit | E1: Basic Rate (Rs)
A2: 0001 | B2: Hire Charges of Plants & Machinery | C2: Hire charges of Coaltar Boiler 900 to 1400 litres | D2: day | E2: 800
A3: 0002 | B3: Hire Charges of Plants & Machinery | C3: Hire charges of Concrete Mixer 0.25 to 0.40 cum with Hopper | D3: day | E3: 800
A4: 0003 | B4: Hire Charges of Plants & Machinery | C4: Hire charges of Diesel Road Roller - 8 to 10 tonne | D4: day | E4: 3000
A5: 0004 | B5: Hire Charges of Plants & Machinery | C5: Production cost of concrete by batch mix plant | D5: cum | E5: 350
A6: 0005 | B6: Hire Charges of Plants & Machinery | C6: Hire charges of Diesel Truck - 9 tonne | D6: day | E6: 2000
A7: 0006 | B7: Hire Charges of Plants & Machinery | C7: Hire charges of Spraying machine including electric charges | D7: day | E7: 250
A8: 0007 | B8: Hire Charges of Plants & Machinery | C8: Hire charges of Coaltar Sprayer | D8: day | E8: 300
A9: 0008 | B9: Hire Charges of Plants & Machinery | C9: Hire charges of Barber green, drying, mixing and Asphalt Plant, | D9: day | E9: 7700
A10: 0009 | B10: Hire Charges of Plants & Machinery | C10: Pumping charges of concrete including Hire charges of pump, | D10: cum | E10: 210
A11: 0010 | B11: Hire Charges of Plants & Machinery | C11: Hire charges of Derrick monkey rope | D11: day | E11: 750
A12: 0011 | B12: Hire Charges of Plants & Machinery | C12: Hire charges of Pump set of capacity 4000 litres/hour | D12: day | E12: 700
A13: 0012 | B13: Hire Charges of Plants & Machinery | C13: Vibrator (Needle type 40 mm) | D13: day | E13: 370
... A2142: 9999 | B2142: Building Materials | C2142: Sundries | D2142: L.S. | E2142: 2

Sheet Global_Factors
A1: CPWD DELHI ANALYSIS OF RATES (DAR 2019) — GLOBAL STATUTORY FACTORS & PROJECT SETTINGS
A2: LEGEND: | B2: Standard Default Value (CPWD DAR 2019) | C2: Project Specific Override (User Input) | D2: Effective Value Used Across Workbook
A4: 1. PROJECT & CONTRACT PARAMETERS
A5: Project Name / Scope of Work: | B5: General Construction & Maintenance Estimates (Non-DSR Items) | D5: CPWD PLANT & MACHINERY HIRE CONVENTION (Item Codes 0001 to 0083): 1. Hire charges include services of operating staff, lubricating oil, diesel/petrol/kerosene, and all consumables for running the machinery, and exclude GST. 2. Hire charges are on per-day basis for a single shift of eight working hours. 3. Do not add duplicate fuel or operator lines unless using un-fueled codes (e.g. 0084 onwards).
A6: Project Location / Zone: | B6: Delhi & National Capital Region (CPWD Circle)
A7: Base Rates Schedule: | B7: CPWD Delhi Analysis of Rates (DAR 2019, Vol. 1)
A8: Location Cost Index: | B8: 118
A10: 2. STATUTORY MARKUPS & OVERHEAD COEFFICIENTS
A11: S.No | B11: Statutory Markup Component | C11: CPWD Default Rate | D11: Basis of Application | E11: Project Override Rate | F11: Effective Rate Applied | G11: CPWD DAR 2019 Rule & Statutory Basis
A12: 1 | B12: Water Charges | C12: 0.01 | D12: Applied on Direct Cost (W) | F12: =IF(E12<>"", E12, C12) -> 0.01 | G12: CPWD Standard: 1.0% on Direct Cost (W) for water consumed in construction/curing. Toggleable on trade sheets.
A13: 2 | B13: Goods and Services Tax (GST) | C13: 0.1405 | D13: Applied on Compounded Base (X = W + Water) | F13: =IF(E13<>"", E13, C13) -> 0.1405 | G13: CPWD DAR 2019 multiplying factor 0.1405 (14.05% effective works contract rate). Override here for 18% (0.18) or 12% (0.12).
A14: 3 | B14: Contractor's Profit & Overheads (CPOH) | C14: 0.15 | D14: Applied on Compounded Base (Y = X + GST) | F14: =IF(E14<>"", E14, C14) -> 0.15 | G14: CPWD DAR Standard: 15.0% for site management, head office overheads, tools, and contractor margin.
A15: 4 | B15: Building & Other Construction Workers Cess (BOCW) | C15: 0.01 | D15: Applied on Compounded Base (Z = Y + CPOH) | F15: =IF(E15<>"", E15, C15) -> 0.01 | G15: Statutory Labour Welfare Cess @ 1.0% per BOCW Welfare Cess Act, 1996.
A16: 5 | B16: Sundries Cost Index Multiplier | C16: 2 | D16: Applied on Base L.S. Allowance (PAR-2012 Base) | F16: =IF(E16<>"", E16, C16) -> 2 | G16: CPWD DAR 2019 Preface: Multiplier of 2.00 on base sundries allowance reflecting Delhi Cost Index (118 vs PAR-2012 base 100).
A18: 3. CPWD SUB-HEAD STATUTORY PRESETS & TRADE CONVENTIONS
A19: Sub-Head Code | B19: Trade Name | C19: Water (1%) | D19: GST (14.05%) | E19: CPOH (15%) | F19: Cess (1%) | G19: CPWD Trade Statutory Convention & Rationale
A20: 01 | B20: Carriage of Materials | C20: NO | D20: NO | E20: YES | F20: NO | G20: Mechanical transport applies 15% CPOH only. Water & Cess omitted (no water used). GST handled separately in freight.
A21: 02 | B21: Earth Work | C21: YES | D21: YES | E21: YES | F21: YES | G21: Standard 5-step compounding chain applied across labour & earthmoving equipment.
A22: 03 | B22: Mortars | C22: NO | D22: NO | E22: NO | F22: NO | G22: Intermediate building block. Stops at direct cost (W). Markup chain is OFF to prevent double taxation when imported into Masonry/Flooring.
A23: 04 | B23: Concrete Work | C23: YES | D23: YES | E23: YES | F23: YES | G23: Standard 5-step compounding chain applied over materials, labour, mixer & vibrator hire.
A24: 05 | B24: RCC Work | C24: YES | D24: YES | E24: YES | F24: YES | G24: Standard 5-step compounding chain. Shuttering and reinforcement are measured & priced separately in CPWD.
A25: 06 | B25: Masonry Work | C25: YES | D25: YES | E25: YES | F25: YES | G25: Imports un-marked Mortar rates as a Material line, then applies full markup chain once over the combined total.
A26: 07 | B26: Stone Work | C26: YES | D26: YES | E26: YES | F26: YES | G26: Imports Mortar rates as Material line; applies full markup chain over stone, mortar, dressing and laying labour.
A27: 08 | B27: Cladding Work | C27: YES | D27: YES | E27: YES | F27: YES | G27: Imports both bedding mortar and pointing mortar rates; applies full markup chain over stone veneer, mortar, scaffolding.
A28: 09 | B28: Wood & PVC Work | C28: YES | D28: YES | E28: YES | F28: YES | G28: Applies full markup chain over timber in scantling (with 5% wastage allowance) and carpentry labour.
A29: 10 | B29: Steel Work | C29: YES | D29: YES | E29: YES | F29: YES | G29: Applies the CPWD (W-A) rule: the priming coat (resolved item 13.50.3) already carries Water, GST, CPOH and Cess, so it is tagged A and every markup is computed on (W-A), (X-A), (Y-A), (Z-A). Verified against DAR item 10.1.
A30: 11 | B30: Flooring | C30: YES | D30: YES | E30: YES | F30: YES | G30: Imports Mortar/Concrete bed rate; applies full markup chain over tiles, stone, laying labour and polishing.
A31: 12 | B31: Roofing | C31: YES | D31: YES | E31: YES | F31: YES | G31: Applies full markup chain over roofing sheets, fixing J-hooks/bolts, limpet washers, and carpenter/fixing labour.

Sheet Labour_Machinery_Productivity
A1: CPWD DAR 2019 - LABOUR & MACHINERY PRODUCTIVITY, ORGANISED BY WORK TYPE (Section 1 = crew summary per work type / Section 2 = full source detail)
A2: Advisory reference only - nothing here is a compute dependency. "Typical Coeff" is the median day-coefficient observed across every DAR item of that work type, at the output basis shown; Low/High give the range actually printed in the book, and Observations says how many item lines back it. Carry a crew into a builder sheet as a starting point, then edit the coefficients to suit the item being priced.
A4: 1. CREW SUMMARY BY WORK TYPE (median day-coefficient per output basis)
A5: Work Type | B5: Trade Group | C5: Resource Type | D5: Code | E5: Resource Description | F5: Unit | G5: Typical Coeff | H5: Low | I5: High | J5: Observations | K5: Output Basis | L5: Basic Rate (Rs)
A6: Carriage - Mechanical Transport | B6: Carriage & Handling | C6: Labour | D6: 0114 | E6: Beldar | F6: day | G6: 4.625 | H6: 2 | I6: 10.66 | J6: 4 | K6: 1 unit | L6: 558
A7: Carriage - Mechanical Transport | B7: Carriage & Handling | C7: Machinery | D7: 0084 | E7: HIre charges of Diesel Truck - 9 tonne excluding diesel & mobile oil | F7: day | G7: 1 | H7: 1 | I7: 1 | J7: 1 | K7: 3 | L7: 1500
A8: Loading / Unloading at Siding | B8: Carriage & Handling | C8: Labour | D8: 0114 | E8: Beldar | F8: day | G8: 3.75 | H8: 3.75 | I8: 3.75 | J8: 1 | K8: 1 unit | L8: 558
A9: Earthwork - Excavation | B9: Earthwork | C9: Labour | D9: 0114 | E9: Beldar | F9: day | G9: 1.1 | H9: 0.06 | I9: 16.5 | J9: 47 | K9: 1 unit | L9: 558
A10: Earthwork - Excavation | B10: Earthwork | C10: Labour | D10: 0112 | E10: Carpenter 2nd class | F10: day | G10: 0.25 | H10: 0.03 | I10: 1.5 | J10: 19 | K10: a manhole 1 | L10: 679
A11: Earthwork - Excavation | B11: Earthwork | C11: Labour | D11: 0115 | E11: Coolie | F11: day | G11: 1.67 | H11: 0.17 | I11: 7 | J11: 12 | K11: 10 cum | L11: 558
A12: Earthwork - Excavation | B12: Earthwork | C12: Labour | D12: 0101 | E12: Bhisti | F12: day | G12: 0.4 | H12: 0.35 | I12: 0.5 | J12: 4 | K12: 10 cum | L12: 617
A13: Earthwork - Excavation | B13: Earthwork | C13: Labour | D13: 0128 | E13: Mate | F13: day | G13: 0.32 | H13: 0.1 | I13: 0.4 | J13: 3 | K13: 10 cum | L13: 617
A14: Earthwork - Excavation | B14: Earthwork | C14: Labour | D14: 0113 | E14: Chowkidar | F14: day | G14: 0.008 | H14: 0.008 | I14: 0.008 | J14: 2 | K14: 10 cum | L14: 558
A15: Earthwork - Excavation | B15: Earthwork | C15: Labour | D15: 0124 | E15: Mason (brick layer) 2nd class | F15: day | G15: 0.275 | H15: 0.05 | I15: 0.5 | J15: 2 | K15: 9 sqm | L15: 679
A16: Earthwork - Excavation | B16: Earthwork | C16: Machinery | D16: 0003 | E16: Hire charges of Diesel Road Roller - 8 to 10 tonne | F16: day | G16: 0.008 | H16: 0.008 | I16: 0.008 | J16: 2 | K16: 10 cum | L16: 3000
A17: Earthwork - Excavation | B17: Earthwork | C17: Machinery | D17: 0018 | E17: Hire and running charges of loader. | F17: day | G17: 0.041 | H17: 0.041 | I17: 0.041 | J17: 2 | K17: 10 cum | L17: 5000
... A179: Painting & Priming | B179: Finishing | C179: Labour | D179: 0131 | E179: Painter | F179: day | G179: 1.13 | H179: 0.15 | I179: 10.37 | J179: 20 | K179: a roof with each sloping side 18 | L179: 679
A181: 2. FULL SOURCE DETAIL (every LABOUR / MACHINERY line mined from the base volumes)
A182: Work Type | B182: Trade Group | C182: Sub-Head | D182: DAR Item No | E182: Item Nomenclature | F182: Output Basis | G182: Resource Type | H182: Code | I182: Resource Description | J182: Unit | K182: Day Coeff / Qty | L182: Basic Rate (Rs)
A183: Carriage - Mechanical Transport | B183: Carriage & Handling | C183: 01_Carriage_of_Materials | F183: 3 | G183: Machinery | H183: 0084 | I183: HIre charges of Diesel Truck - 9 tonne excluding diesel & mobile oil | J183: day | K183: 1 | L183: 1500
A184: Carriage - Mechanical Transport | B184: Carriage & Handling | C184: 01_Carriage_of_Materials | F184: 3 | G184: Labour | H184: 0114 | I184: Beldar | J184: day | K184: 6 | L184: 558
A185: Carriage - Mechanical Transport | B185: Carriage & Handling | C185: 01_Carriage_of_Materials | F185: 3 | G185: Labour | H185: 0114 | I185: Beldar | J185: day | K185: 0 | L185: 558
A186: Carriage - Mechanical Transport | B186: Carriage & Handling | C186: 01_Carriage_of_Materials | F186: 3 | G186: Labour | H186: 0115 | I186: Coolie | J186: day | K186: 0 | L186: 558
A187: Carriage - Mechanical Transport | B187: Carriage & Handling | C187: 01_Carriage_of_Materials | D187: 1.2.10 | E187: Steam Coal | F187: 1 unit | G187: Labour | H187: 0114 | I187: Beldar | J187: Day | K187: 0 | L187: 558
A188: Carriage - Mechanical Transport | B188: Carriage & Handling | C188: 01_Carriage_of_Materials | D188: 1.2.10 | E188: Steam Coal | F188: 1 unit | G188: Labour | H188: 0115 | I188: Coolie | J188: Day | K188: 0 | L188: 558
A189: Carriage - Mechanical Transport | B189: Carriage & Handling | C189: 01_Carriage_of_Materials | D189: 1.4.1 | E189: Steel Details of 44 tonnes of steel LABOUR | F189: 1 unit | G189: Labour | H189: 0114 | I189: Beldar | J189: day | K189: 10.66 | L189: 558
A190: Carriage - Mechanical Transport | B190: Carriage & Handling | C190: 01_Carriage_of_Materials | D190: 1.4.2 | E190: G.I., C.I., R.C.C. or C.C. pipes upto 500 mm dia and similar heavy materials Details of cost of unlo | F190: 1 unit | G190: Labour | H190: 0114 | I190: Beldar | J190: day | K190: 2 | L190: 558
A191: Carriage - Mechanical Transport | B191: Carriage & Handling | C191: 01_Carriage_of_Materials | D191: 1.4.2 | E191: G.I., C.I., R.C.C. or C.C. pipes upto 500 mm dia and similar heavy materials Details of cost of unlo | F191: 1 unit | G191: Labour | H191: 0114 | I191: Beldar | J191: day | K191: 3.25 | L191: 558
A192: Loading / Unloading at Siding | B192: Carriage & Handling | C192: 01_Carriage_of_Materials | D192: 1.3 | E192: Loading in or unloading cement from the railway wagons at siding and carrying the same from or into | F192: 1 unit | G192: Labour | H192: 0114 | I192: Beldar | J192: day | K192: 3.75 | L192: 558
A193: Earthwork - Excavation | B193: Earthwork | C193: 02_Earth_Work | D193: 1.2.2 | E193: Rate as per item no 1.2.2 of | F193: 1 unit | G193: Labour | H193: 0114 | I193: Beldar (1/2x0.89=0.45 day) | J193: day | K193: 0.45 | L193: 558
A194: Earthwork - Excavation | B194: Earthwork | C194: 02_Earth_Work | D194: 1.2.2 | E194: Rate as per item no 1.2.2 of | F194: 1 unit | G194: Labour | H194: 0101 | I194: Bhisti | J194: day | K194: 0.35 | L194: 617
A195: Earthwork - Excavation | B195: Earthwork | C195: 02_Earth_Work | D195: 2.1.1 | E195: All kinds of soil Details of cost for 100 Sqm LABOUR | F195: 100 Sqm | G195: Labour | H195: 0114 | I195: Beldar | J195: day | K195: 6.8 | L195: 558
A196: Earthwork - Excavation | B196: Earthwork | C196: 02_Earth_Work | D196: 2.1.1 | E196: All kinds of soil Details of cost for 100 Sqm LABOUR | F196: 100 Sqm | G196: Labour | H196: 0115 | I196: Coolie | J196: day | K196: 5.6 | L196: 558
A197: Earthwork - Excavation | B197: Earthwork | C197: 02_Earth_Work | D197: 2.16.1 | E197: Depth not exceeding 1.5 m Details of cost for a trench 30m long and 1.5m deep area 2x30x1.50=90 sqm | F197: a trench 30m long and 1 | G197: Labour | H197: 0112 | I197: Carpenter 2nd class | J197: day | K197: 0.5 | L197: 679
A198: Earthwork - Excavation | B198: Earthwork | C198: 02_Earth_Work | D198: 2.16.1 | E198: Depth not exceeding 1.5 m Details of cost for a trench 30m long and 1.5m deep area 2x30x1.50=90 sqm | F198: a trench 30m long and 1 | G198: Labour | H198: 0114 | I198: Beldar | J198: day | K198: 1 | L198: 558
... A3206: Painting & Priming | B3206: Finishing | C3206: 12_Roofing | D3206: 12.63 | E3206: Providing and applying two coats of High Albedo paint having minimum Solar Reflective Index (SRI) 10 | F3206: 10 Sqm | G3206: Labour | H3206: 0131 | I3206: Painter | J3206: day | K3206: 0.54 | L3206: 679

Sheet Sundries_Reference
A1: Sub-Head | B1: DAR Item No | C1: Item Nomenclature | D1: Output Basis | E1: Sundries Description | F1: Base L.S. Quantity | G1: Index Multiplier | H1: Total Amount (Rs)
A2: 01_Carriage_of_Materials | B2: 1.3 | C2: Loading in or unloading cement from the railway wagons at siding and carrying the same from or into | D2: 1 unit | E2: Sundries Add for sweeping the wagon, screening the swept cement and filling the same in bags | F2: 2.62 | G2: 2 | H2: 5.24
A3: 01_Carriage_of_Materials | B3: 1.4.2 | C3: G.I., C.I., R.C.C. or C.C. pipes upto 500 mm dia and similar heavy materials Details of cost of unlo | D3: 1 unit | E3: Sundries | F3: 3.1 | G3: 2 | H3: 6.2
A4: 01_Carriage_of_Materials | B4: 1.4.2 | C4: G.I., C.I., R.C.C. or C.C. pipes upto 500 mm dia and similar heavy materials Details of cost of unlo | D4: 1 unit | E4: Extra for fixing crane including labour involved | F4: 91.15 | G4: 2 | H4: 182.3
A5: 01_Carriage_of_Materials | B5: 1.4.2 | C5: G.I., C.I., R.C.C. or C.C. pipes upto 500 mm dia and similar heavy materials Details of cost of unlo | D5: 1 unit | E5: Sundries | F5: 7.4 | G5: 2 | H5: 14.8
A6: 02_Earth_Work | B6: 2.2.1 | C6: All kinds of soil Details of cost for 10 cum. LABOUR | D6: 10 cum | E6: Sundries | F6: 2.73 | G6: 2 | H6: 5.46
A7: 02_Earth_Work | B7: 2.3.1 | C7: All kinds of soil Details of cost for 10 cum. LABOUR | D7: 10 cum | E7: Sundries | F7: 2.73 | G7: 2 | H7: 5.46
A8: 02_Earth_Work | B8: 2.4 | C8: Deduct for not rolling with power roller of minimum 8 tonnes for banking excavated earth in layers n | D8: 10 cum | E8: Sundries | F8: 1.82 | G8: 2 | H8: 3.64
A9: 02_Earth_Work | B9: 2.7.1 | C9: Ordinary rock Details of cost for 10 cum. MACHINERY | D9: 10 cum | E9: Sundries | F9: 10.79 | G9: 2 | H9: 21.58
A10: 02_Earth_Work | B10: 2.7.2 | C10: Hard rock (requiring blasting) Details of cost for 10 cum. MACHINERY | D10: 10 cum | E10: Sundries | F10: 16.12 | G10: 2 | H10: 32.24
A11: 02_Earth_Work | B11: 2.7.3 | C11: Hard rock (blasting prohibited) Details of cost for 10 cum. MACHINERY | D11: 10 cum | E11: Sundries | F11: 16.12 | G11: 2 | H11: 32.24
A12: 02_Earth_Work | B12: 2.9.1 | C12: Ordinary rock Details of cost for 10 cum. MACHINERY | D12: 10 cum | E12: Sundries | F12: 13.52 | G12: 2 | H12: 27.04
A13: 02_Earth_Work | B13: 2.9.2 | C13: Hard rock (requiring blasting) Details of cost for 10 cum. MACHINERY | D13: 10 cum | E13: Sundries | F13: 18.85 | G13: 2 | H13: 37.7
... A1218: 12_Roofing | B1218: 12.63 | C1218: Providing and applying two coats of High Albedo paint having minimum Solar Reflective Index (SRI) 10 | D1218: 10 Sqm | E1218: Sundries (Brushes & T&P etc. | F1218: 13.52 | G1218: 2 | H1218: 27.04

Sheet Resolved_Cross_Volume_Items
A1: CPWD DAR 2019 - RESOLVED CROSS-VOLUME ITEMS (Vol.2 items re-derived from WB1 data only)
A2: LEGEND: | B2: User Input (Editable) | C2: Auto Lookup from Rates_Master | D2: Calculated | E2: Resolved Rate | F2: CPWD Rule / Note
A3: Vol.1 builder sheets 08, 09 and 10 need four items printed in Vol.2. Each is re-derived here line-by-line from this workbook's own Rates_Master catalogue and computed to a final rate, so WB1 never needs Vol.2 open. Consuming sheets reference the RESULT (see summary below), and tag that line "A" so it is excluded from their own markup chain per the CPWD (W-A) convention.
A5: 1. RESOLVED RATE SUMMARY (referenced by the consuming builder sheets)
A6: Item No | B6: Source Sub-Head | C6: Nomenclature | D6: Unit | E6: Basis | F6: DAR 2019 Printed Rate | G6: Resolved Rate (live) | H6: Defined Name | I6: Consumed By
A7: 4.2.5 | B7: 04 Concrete Work (Vol.1) | C7: Providing and laying in position cement concrete of specified grade excluding the cost of centering and shuttering - 1:3:6 (1 cement : 3 coarse sand (zone-III) : 6 graded stone aggregate 20 mm nominal size) | D7: cum | E7: 1 | F7: 8025 | G7: =G44 -> 8025 | H7: XV_4_2_5 | I7: Feeds resolved item 18.78 below (not a Vol.2 item - re-derived here so 18.78 is self-contained)
A8: 13.50.1 | B8: 13 Finishing (Vol.2) | C8: Applying priming coat with ready mixed pink or Grey primer of approved brand and manufacture on wood work (hard and soft wood) | D8: sqm | E8: 10 | F8: 57.05 | G8: =G66 -> 57.05 | H8: XV_13_50_1 | I8: 09_Wood_and_PVC_Work (primer on wood work)
A9: 13.50.3 | B9: 13 Finishing (Vol.2) | C9: Applying priming coat with ready mixed red oxide zinc chromate primer of approved brand and manufacture on steel / iron work | D9: sqm | E9: 10 | F9: 50.7 | G9: =G86 -> 50.7 | H9: XV_13_50_3 | I9: 10_Steel_Work (priming coat), 09_Wood_and_PVC_Work (steel fittings)
A10: 13.57.1 | B10: 13 Finishing (Vol.2) | C10: Painting with oil type wood preservative of approved brand and manufacture - new work (two or more coats) | D10: sqm | E10: 10 | F10: 44.5 | G10: =G107 -> 44.5 | H10: XV_13_57_1 | I10: 09_Wood_and_PVC_Work (preservative treatment on timber)
A11: 18.78 | B11: 18 Water Supply (Vol.2) | C11: Making chases up to 7.5 x 7.5 cm in walls including making good and finishing the same with cement concrete 1:3:6 | D11: metre | E11: 10 | F11: 154.15 | G11: =G126 -> 154.15 | H11: XV_18_78 | I11: 08_Cladding_Work (chase cutting for concealed fixings / services)
A13: 2. FULL LINE-BY-LINE BREAKDOWNS (every rate traced to Rates_Master)
A14: ITEM 4.2.5 - 04 Concrete Work (Vol.1) - Providing and laying in position cement concrete of specified grade excluding the cost of centering and shuttering - 1:3:6 (1 cement : 3 coarse sand (zone-III) : 6 graded stone aggregate 20 mm nominal size)
A15: Basis: | B15: 1 | C15: cum | D15: Consumed by: | E15: Feeds resolved item 18.78 below (not a Vol.2 item - re-derived here so 18.78 is self-contained)
A16: Line | B16: Code / Source | C16: Description / Specification | D16: Unit | E16: Quantity / Coeff | F16: Basic Rate (Rs) | G16: Amount (Rs) | H16: Source Reference / Remarks | I16: Markup Tag
A17: 1 | B17: 0295 | C17: =IFERROR(INDEX(Rates_Master!$C:$C, MATCH(B17, Rates_Master!$A:$A, 0)), "Code not found in Rates_Master") -> Stone Aggregate (Single size) : 20 mm nominal size | D17: =IFERROR(INDEX(Rates_Master!$D:$D, MATCH(B17, Rates_Master!$A:$A, 0)), "") -> cum | E17: 0.7 | F17: =IFERROR(INDEX(Rates_Master!$E:$E, MATCH(B17, Rates_Master!$A:$A, 0)), 0) -> 1350 | G17: =ROUND(E17 * F17, 2) -> 945 | H17: Stone Aggregate (single size) 20 mm nominal size
A18: 2 | B18: 0297 | C18: =IFERROR(INDEX(Rates_Master!$C:$C, MATCH(B18, Rates_Master!$A:$A, 0)), "Code not found in Rates_Master") -> Stone Aggregate (Single size) : 10 mm nominal size | D18: =IFERROR(INDEX(Rates_Master!$D:$D, MATCH(B18, Rates_Master!$A:$A, 0)), "") -> cum | E18: 0.24 | F18: =IFERROR(INDEX(Rates_Master!$E:$E, MATCH(B18, Rates_Master!$A:$A, 0)), 0) -> 1350 | G18: =ROUND(E18 * F18, 2) -> 324 | H18: Stone Aggregate (single size) 10 mm nominal size
A19: 3 | B19: 2202 | C19: =IFERROR(INDEX(Rates_Master!$C:$C, MATCH(B19, Rates_Master!$A:$A, 0)), "Code not found in Rates_Master") -> Carriage of Stone aggregate below 40 mm nominal size | D19: =IFERROR(INDEX(Rates_Master!$D:$D, MATCH(B19, Rates_Master!$A:$A, 0)), "") -> cum | E19: 0.94 | F19: =IFERROR(INDEX(Rates_Master!$E:$E, MATCH(B19, Rates_Master!$A:$A, 0)), 0) -> 103.77 | G19: =ROUND(E19 * F19, 2) -> 97.54 | H19: Carriage of Stone aggregate below 40 mm nominal size
A20: 4 | B20: 0982 | C20: =IFERROR(INDEX(Rates_Master!$C:$C, MATCH(B20, Rates_Master!$A:$A, 0)), "Code not found in Rates_Master") -> Coarse sand (zone III) | D20: =IFERROR(INDEX(Rates_Master!$D:$D, MATCH(B20, Rates_Master!$A:$A, 0)), "") -> cum | E20: 0.47 | F20: =IFERROR(INDEX(Rates_Master!$E:$E, MATCH(B20, Rates_Master!$A:$A, 0)), 0) -> 1350 | G20: =ROUND(E20 * F20, 2) -> 634.5 | H20: Coarse sand (zone III)
A21: 5 | B21: 2203 | C21: =IFERROR(INDEX(Rates_Master!$C:$C, MATCH(B21, Rates_Master!$A:$A, 0)), "Code not found in Rates_Master") -> Carriage of Coarse sand | D21: =IFERROR(INDEX(Rates_Master!$D:$D, MATCH(B21, Rates_Master!$A:$A, 0)), "") -> cum | E21: 0.47 | F21: =IFERROR(INDEX(Rates_Master!$E:$E, MATCH(B21, Rates_Master!$A:$A, 0)), 0) -> 103.77 | G21: =ROUND(E21 * F21, 2) -> 48.77 | H21: Carriage of Coarse sand
A22: 6 | B22: 0367 | C22: =IFERROR(INDEX(Rates_Master!$C:$C, MATCH(B22, Rates_Master!$A:$A, 0)), "Code not found in Rates_Master") -> Portland Cement (OPC-43 Grade) | D22: =IFERROR(INDEX(Rates_Master!$D:$D, MATCH(B22, Rates_Master!$A:$A, 0)), "") -> tonne | E22: 0.22 | F22: =IFERROR(INDEX(Rates_Master!$E:$E, MATCH(B22, Rates_Master!$A:$A, 0)), 0) -> 4940 | G22: =ROUND(E22 * F22, 2) -> 1086.8 | H22: Portland Cement (0.15674 cum = 0.22 tonne)
A23: 7 | B23: 2209 | C23: =IFERROR(INDEX(Rates_Master!$C:$C, MATCH(B23, Rates_Master!$A:$A, 0)), "Code not found in Rates_Master") -> Carriage of Cement | D23: =IFERROR(INDEX(Rates_Master!$D:$D, MATCH(B23, Rates_Master!$A:$A, 0)), "") -> tonne | E23: 0.22 | F23: =IFERROR(INDEX(Rates_Master!$E:$E, MATCH(B23, Rates_Master!$A:$A, 0)), 0) -> 92.24 | G23: =ROUND(E23 * F23, 2) -> 20.29 | H23: Carriage of Cement
A24: 8 | B24: 0114 | C24: =IFERROR(INDEX(Rates_Master!$C:$C, MATCH(B24, Rates_Master!$A:$A, 0)), "Code not found in Rates_Master") -> Beldar | D24: =IFERROR(INDEX(Rates_Master!$D:$D, MATCH(B24, Rates_Master!$A:$A, 0)), "") -> day | E24: 0.9 | F24: =IFERROR(INDEX(Rates_Master!$E:$E, MATCH(B24, Rates_Master!$A:$A, 0)), 0) -> 558 | G24: =ROUND(E24 * F24, 2) -> 502.2 | H24: Beldar
A25: 9 | B25: 0115 | C25: =IFERROR(INDEX(Rates_Master!$C:$C, MATCH(B25, Rates_Master!$A:$A, 0)), "Code not found in Rates_Master") -> Coolie | D25: =IFERROR(INDEX(Rates_Master!$D:$D, MATCH(B25, Rates_Master!$A:$A, 0)), "") -> day | E25: 0.78 | F25: =IFERROR(INDEX(Rates_Master!$E:$E, MATCH(B25, Rates_Master!$A:$A, 0)), 0) -> 558 | G25: =ROUND(E25 * F25, 2) -> 435.24 | H25: Coolie
A26: 10 | B26: 0101 | C26: =IFERROR(INDEX(Rates_Master!$C:$C, MATCH(B26, Rates_Master!$A:$A, 0)), "Code not found in Rates_Master") -> Bhisti | D26: =IFERROR(INDEX(Rates_Master!$D:$D, MATCH(B26, Rates_Master!$A:$A, 0)), "") -> day | E26: 0.7 | F26: =IFERROR(INDEX(Rates_Master!$E:$E, MATCH(B26, Rates_Master!$A:$A, 0)), 0) -> 617 | G26: =ROUND(E26 * F26, 2) -> 431.9 | H26: Bhisti
A27: 11 | B27: 0123 | C27: =IFERROR(INDEX(Rates_Master!$C:$C, MATCH(B27, Rates_Master!$A:$A, 0)), "Code not found in Rates_Master") -> Mason (brick layer) 1st class | D27: =IFERROR(INDEX(Rates_Master!$D:$D, MATCH(B27, Rates_Master!$A:$A, 0)), "") -> day | E27: 0.06 | F27: =IFERROR(INDEX(Rates_Master!$E:$E, MATCH(B27, Rates_Master!$A:$A, 0)), 0) -> 738 | G27: =ROUND(E27 * F27, 2) -> 44.28 | H27: Mason (brick layer) 1st class
A28: 12 | B28: 0124 | C28: =IFERROR(INDEX(Rates_Master!$C:$C, MATCH(B28, Rates_Master!$A:$A, 0)), "Code not found in Rates_Master") -> Mason (brick layer) 2nd class | D28: =IFERROR(INDEX(Rates_Master!$D:$D, MATCH(B28, Rates_Master!$A:$A, 0)), "") -> day | E28: 0.06 | F28: =IFERROR(INDEX(Rates_Master!$E:$E, MATCH(B28, Rates_Master!$A:$A, 0)), 0) -> 679 | G28: =ROUND(E28 * F28, 2) -> 40.74 | H28: Mason (brick layer) 2nd class
... A31: 15 | B31: 0115 | C31: =IFERROR(INDEX(Rates_Master!$C:$C, MATCH(B31, Rates_Master!$A:$A, 0)), "Code not found in Rates_Master") -> Coolie | D31: =IFERROR(INDEX(Rates_Master!$D:$D, MATCH(B31, Rates_Master!$A:$A, 0)), "") -> day | E31: 1.88 | F31: =IFERROR(INDEX(Rates_Master!$E:$E, MATCH(B31, Rates_Master!$A:$A, 0)), 0) -> 558 | G31: =ROUND(E31 * F31, 2) -> 1049.04 | H31: Coolie - extra labour lifting material upto floor V level (0.75 x 2.5 = 1.88)
A32: 16 | B32: 9999 | C32: Scaffolding (17.60 x 2.5 avg.) | D32: L.S. | E32: 114.4 | F32: =Factor_Sundries -> 2 | G32: =ROUND(E32 * F32, 2) -> 228.8 | H32: Base L.S. allowance x Cost Index Multiplier (Global_Factors)
A33: 17 | B33: 9999 | C33: Sundries | D33: L.S. | E33: 13.52 | F33: =Factor_Sundries -> 2 | G33: =ROUND(E33 * F33, 2) -> 27.04 | H33: Base L.S. allowance x Cost Index Multiplier (Global_Factors)
A34: TOTAL DIRECT COST "W" (all lines above): | G34: =ROUND(SUM(G17:G33), 2) -> 5998.04 | H34: Book value of W for item 4.2.5 = Rs 5,998.05
A35: Less "A" - imported lines already carrying statutory markups: | G35: =ROUND(SUMIF($I$17:$I$33, "A", $G$17:$G$33), 2) -> 0 | H35: CPWD convention: markups are computed on (W-A), (X-A), (Y-A), (Z-A). A line tagged "A" is an imported rate that already includes Water, GST, CPOH and Cess.
A36: X1 | B36: YES | C36: Add Water Charges on (W - A) | E36: =G34 - G35 -> 5998.04 | F36: =Factor_Water -> 0.01 | G36: =IF(B36="YES", ROUND(E36 * F36, 2), 0) -> 59.98 | H36: CPWD: 1% water charges, computed on the direct cost net of A-tagged imports.
A37: X | B37: - | C37: Subtotal "X" (W + Water Charges) | G37: =G34 + G36 -> 6058.02 | H37: Running compounded subtotal
A38: Y1 | B38: YES | C38: Add GST on (X - A) | E38: =G37 - G35 -> 6058.02 | F38: =Factor_GST -> 0.1405 | G38: =IF(B38="YES", ROUND(E38 * F38, 2), 0) -> 851.15 | H38: CPWD DAR 2019 works contract multiplying factor 0.1405, net of A.
A39: Y | B39: - | C39: Subtotal "Y" (X + GST) | G39: =G37 + G38 -> 6909.17 | H39: Running compounded subtotal
A40: Z1 | B40: YES | C40: Add Contractor Profit & Overheads on (Y - A) | E40: =G39 - G35 -> 6909.17 | F40: =Factor_CPOH -> 0.15 | G40: =IF(B40="YES", ROUND(E40 * F40, 2), 0) -> 1036.38 | H40: Standard 15% CPOH, net of A.
A41: Z | B41: - | C41: Subtotal "Z" (Y + CPOH) | G41: =G39 + G40 -> 7945.55 | H41: Running compounded subtotal
A42: Z2 | B42: YES | C42: Add BOCW Welfare Cess on (Z - A) | E42: =G41 - G35 -> 7945.55 | F42: =Factor_Cess -> 0.01 | G42: =IF(B42="YES", ROUND(E42 * F42, 2), 0) -> 79.46 | H42: Statutory 1% BOCW Welfare Cess, net of A.
A43: Cost of 1.00 cum: | G43: =ROUND(G41 + G42, 2) -> 8025.01
A44: RESOLVED RATE per 1.00 cum (SAY): | G44: =MROUND(G43 / 1, 0.05) -> 8025 | H44: CPWD DAR 2019 printed Say rate for this item = Rs 8,025.00 per cum. Rounded with MROUND(x, 0.05) because CPWD quotes every Say rate to the nearest 5 paise. Any difference means a Rates_Master rate has been edited away from the 2019 base.
...

Sheet 01_Carriage_of_Materials
A1: CPWD DAR 2019 — SUB-HEAD 01: CARRIAGE OF MATERIALS (ANALYTICAL SIMULATOR & BENCHMARKS)
A2: LEGEND: | B2: INPUT - you type it | C2: OVERRIDE - optional | D2: LOOKUP - fetched | E2: DERIVED - calculated | F2: RESULT - subtotal | G2: SAY - final rate | H2: CPWD rule / note | I2: Not editable
A3: CPWD DAR Sub-head 01: Dynamic Mechanical Carriage Simulator based on Data Sheet No. 1 (Notes 1 to 5). Supports custom lead (L), truck speed (S), turnaround time (T), and payload capacities (C). Evaluates trips N, km done, dynamic fuel consumption, and net unit rates with 15% CPOH.
A4: HOW TO USE THIS SHEET (read this before typing anything)
A5: HOW TO USE THIS SHEET - STEP 1: fill in PANEL 1 to say WHAT is being built; each row tells you whether that choice actually changes the cost. STEP 2: set the quantities in PANEL 2. STEP 3: enter the MATERIAL and LABOUR lines - type a code in the yellow "Code / Source" cell and the description, unit and rate fill themselves in. STEP 4: read the gold SAY rate at the bottom. Everything between Step 3 and the SAY rate is calculated for you - if a cell is not yellow or orange, do not type in it.
A6: WHAT THE COLOURS MEAN - YELLOW = INPUT, you type it. ORANGE = OVERRIDE, optional; leave it blank to use the looked-up value, or type here to force your own. BLUE = LOOKUP, fetched from Rates_Master or another reference sheet. WHITE = DERIVED, calculated from the cells above it. GREEN = a subtotal to read. GOLD = the final SAY rate. The sheet is protected, so only the yellow and orange cells will let you type at all.
A8: QUICK RATE LOOKUP - READ A READY-MADE CPWD RATE OFF TABLE 1.1. Pick a material and type a lead: the rate below is the one the DAR 2019 already publishes. For anything the book covers you can stop here - the rest of this sheet is only needed when you are pricing something the book does NOT cover.
A9: Parameter | B9: Value | C9: Unit | D9: Cell Role | E9: Where this value comes from, and the CPWD DAR 2019 basis for it
A10: Material to be carried | B10: R.C.C. / C.I. / steel pipes 1000, 1100 & 1200 mm dia | C10: - | D10: INPUT | E10: Pick any of the 37 materials the DAR tabulates in Table 1.1 (section 5B below).
A11: Lead distance | B11: 10 | C11: km | D11: INPUT | E11: One-way haul distance. Any value from 1 km upwards - the book covers up to 30 km directly and beyond that by its per-km band rate.
A12: Table 1.1 row matched | B12: =IFERROR(MATCH(B10, $B$180:$B$216, 0), "") -> 37 | C12: row | D12: DERIVED | E12: Which row of Table 1.1 your material is on.
A13: Rate is per | B13: =IFERROR(INDEX($E$180:$E$216, B12), "") -> 100 m | C13: - | D13: LOOKUP | E13: The DAR schedule unit for this material - the rate below is per ONE of these.
A14: Which part of the table applies | B14: =IF(B12="", "", IF(B11<=5, "Printed column for " & TEXT(MAX(1,CEILING(B11,1)),"0") & " km", IF(B11<=10, "5 km rate + column L per km", IF(B11<=20, "10 km rate + column M per km", "20 km rate + column N per km")))) -> 5 km rate + column L per km | C14: - | D14: DERIVED | E14: The DAR prints exact rates for 1, 2, 3, 4 and 5 km (Table 1.1 columns G to K). Past 5 km it stops printing whole rates and instead gives a PER-KILOMETRE adder for three bands: column L for >5-10 km, column M for >10-20 km, column N for >20 km. This row says which of those four cases your lead falls into.
A15: Base rate taken from the table | B15: =IF(B12="", "", IF(B11<=5, CHOOSE(MAX(1,MIN(5,CEILING(B11,1))), INDEX($G$180:$G$216,B12), INDEX($H$180:$H$216,B12), INDEX($I$180:$I$216,B12), INDEX($J$180:$J$216,B12), INDEX($K$180:$K$216,B12)), IF(B11<=10, INDEX($K$180:$K$216,B12), IF(B11<=20, INDEX($K$180:$K$216,B12) + 5*INDEX($L$180:$L$216,B12), INDEX($K$180:$K$216,B12) + 5*INDEX($L$180:$L$216,B12) + 10*INDEX($M$180:$M$216,B12))))) -> 11764.25 | C15: Rs | D15: LOOKUP | E15: The printed rate the calculation starts from: the 1-5 km column itself, or the 5 km / 10 km / 20 km rate that the relevant band builds on.
A16: Kilometres beyond the base | B16: =IF(B12="", "", IF(B11<=5, 0, IF(B11<=10, B11-5, IF(B11<=20, B11-10, B11-20)))) -> 5 | C16: km | D16: DERIVED | E16: How far past the base rate's lead you are travelling. Zero for leads up to 5 km, because those rates are printed outright.
A17: Per-km rate for that band | B17: =IF(B12="", "", IF(B11<=5, 0, IF(B11<=10, INDEX($L$180:$L$216,B12), IF(B11<=20, INDEX($M$180:$M$216,B12), INDEX($N$180:$N$216,B12))))) -> 886.17 | C17: Rs per km | D17: LOOKUP | E17: Straight out of Table 1.1 column L, M or N depending on the band. This is exactly what those three columns are FOR - they are adders, not rates in their own right.
A18: Add for the extra distance | B18: =IF(B12="", "", ROUND(B16 * B17, 2)) -> 4430.85 | C18: Rs | D18: DERIVED | E18: Kilometres beyond the base x the per-km rate for the band.
A19: CPWD PUBLISHED CARRIAGE RATE | B19: =IF(B12="", "", ROUND(B15 + B18, 2)) -> 16195.1 | C19: Rs | D19: SAY | E19: Base rate + the extra for distance. This is the DAR 2019 rate for this material at this lead, including 15% CP&OH, per the unit shown three rows up. You can put this straight into an estimate.
A20: How that number was reached | B20: =IF(B12="", "Pick a material from the dropdown above to see the book rate.", "Carriage of " & B10 & " for a lead of " & TEXT(B11,"0.00") & " km = " & IF(B11<=5, "Rs " & TEXT(B15,"#,##0.00") & " read directly from the " & TEXT(MAX(1,CEILING(B11,1)),"0") & " km column of Table 1.1", "Rs " & TEXT(B15,"#,##0.00") & " (the " & IF(B11<=10,"5",IF(B11<=20,"10","20")) & " km rate) plus " & TEXT(B16,"0.00") & " km x Rs " & TEXT(B17,"#,##0.00") & " per km = Rs " & TEXT(B18,"#,##0.00")) & ", giving Rs " & TEXT(B19,"#,##0.00") & " per " & B13 & ".") -> Carriage of R.C.C. / C.I. / steel pipes 1000, 1100 & 1200 mm dia for a lead of 10.00 km = Rs 11,764.25 (the 5 km rate) plus 5.00 km x Rs 886.17 per km = Rs 4,430.85, giving Rs 16,195.10 per 100 m.
A22: PANEL 1 - SCOPE & SPECIFICATION (what is being moved, and under what contract scope)
A23: Parameter | B23: Value | C23: Unit | D23: Cell Role | E23: Where this value comes from, and the CPWD DAR 2019 basis for it
A24: Custom item code | B24: 1.1.CUSTOM | C24: - | D24: INPUT | E24: Your reference for this analysis. Pick a DAR item number from the dropdown to base it on a printed item, or type your own code for a genuinely non-DSR item.
A25: Material commodity | B25: R.C.C. / C.I. / steel pipes 1000, 1100 & 1200 mm dia | C25: - | D25: INPUT | E25: DRIVES COST. Sets the truck payload, the net payable quantity and the billing unit, all looked up from Table 1.1 below. Choose from the dropdown so the lookups resolve.
A26: Handling scope | B26: including loading, transporting, unloading and stacking | C26: - | D26: INPUT | E26: DRIVES COST. Sets the Beldar gang on the resource schedule below: 6 for full turnkey handling, 5 without stacking, 3 when machine-loaded, 3.75 at a railway siding, 0 for pure haulage. See the scope table at the bottom of this sheet.
A27: Lift condition | B27: for all lifts | C27: - | D27: INPUT | E27: NOMENCLATURE ONLY. The DAR quotes one carriage rate whatever the lift, so this changes the wording of the item and nothing in the cost.
A28: Municipal gate / tipping fee | B28: 0 | C28: Rs per billing unit | D28: INPUT | E28: USER-SUPPLIED COST. The DAR carries no tipping or gate fee anywhere in Sub-Head 01, so there is no figure to look up. It is added AFTER the markup chain and is therefore NOT subject to the 15% CPOH - it is a reimbursable disbursement, not contractor cost.
A29: Nomenclature override | C29: - | D29: OVERRIDE | E29: Leave blank and the item description below writes itself from your Panel 1 choices. Type here only when you want to word the item yourself.
A30: Assembled item nomenclature | B30: =IF(B29<>"", B29, "Carriage of " & B25 & " by mechanical transport " & B26 & " for lead upto " & TEXT(B34, "0.00") & " km " & B27 & IF(B28>0, ", including municipal tipping / gate fee of Rs " & TEXT(B28, "0.00") & " per " & B55, "") & ", complete as per directions of Engineer-in-charge.") -> Carriage of R.C.C. / C.I. / steel pipes 1000, 1100 & 1200 mm dia by mechanical transport including loading, transporting, unloading and stacking for lead upto 26.00 km for all lifts, complete as per directions of Engineer-in-charge.
A32: PANEL 2 - ROUTE & TRIP DYNAMICS (how far, how fast, how many trips a shift)
A33: Parameter | B33: Value | C33: Unit | D33: Cell Role | E33: Where this value comes from, and the CPWD DAR 2019 basis for it
A34: Lead distance (L) | B34: 26 | C34: km | D34: INPUT | E34: DRIVES COST. One-way haul distance. Everything below - speed, trips, fuel - follows from it.
A35: Benchmark average speed at this lead | B35: =IFERROR(INDEX($B$146:$B$175, MATCH(B34, $A$146:$A$175, 1)), 16) -> 29 | C35: km/h | D35: LOOKUP | E35: Read off CPWD Data Sheet No. 1 (section 5A below) for the lead above: 16 km/h at 1 km rising to 31 km/h at 30 km. Beyond 30 km the last tabulated row is used.
A36: Speed override | C36: km/h | D36: OVERRIDE | E36: Leave blank to use the Data Sheet 1 benchmark above. Fill it in only when site conditions genuinely differ, and record why - departing from the benchmark is what makes a rate non-DSR.
A37: Effective average speed (S) | B37: =IF(B36<>"", B36, B35) -> 29 | C37: km/h | D37: DERIVED | E37: The override if you gave one, otherwise the benchmark. This is the S used in the trips formula.
A38: Turnaround time (T) | B38: 1 | C38: hours per trip | D38: INPUT | E38: Loading plus unloading plus waiting per round trip. CPWD Data Sheet 1 uses 1.00 hour.
A39: Operational mode | B39: STANDARD (DAYTIME) | C39: - | D39: INPUT | E39: Urban restricted hours means heavy vehicles may only run off-peak, which caps the trips achievable in a shift. Selecting it does not change the cost by itself - enter the capped trip count in the override on the next row. DAR item 1.1.18 is the worked example: 3.00 trips instead of the 4.10 the formula gives at 10 km.
A40: Trip count basis | B40: CPWD FRACTIONAL (Data Sheet 1 basis) | C40: - | D40: INPUT | E40: CPWD FRACTIONAL is the book's own basis and the default. Data Sheet No. 1 quotes trips as decimals throughout - 7.11 at 1 km, 4.10 at 10 km, 2.73 at 30 km - because N is a productivity RATE per 8-hour shift, not a count of trips on one particular day; the truck is hired by the day and the cost is spread over the average output. WHOLE TRIPS rounds down to an integer, which is defensible when a real site or regulatory constraint caps the trips, but it does NOT reproduce the printed DAR rates - flooring 7.11 to 7 at 1 km raises the lime/moorum rate from Rs 104.94 to Rs 106.52. Where the DAR itself fixes a whole trip count (item 1.1.18 uses exactly 3.00 under urban restricted hours) it does so as an explicit cap, not as a rounding rule - use the Trips override below for that.
A41: Trips override | C41: trips per shift | D41: OVERRIDE | E41: Leave blank to use the calculated trips below. Fill it in to force a trip count - this is how a restricted-hours item is priced. It is honoured in any mode.
A42: Daily trips achieved (N) | B42: =IF(B41<>"", B41, IF(B40="WHOLE TRIPS (round down to integer)", IFERROR(INT(8 / ((2 * B34 / B37) + B38)), 0), IFERROR(ROUND(8 / ((2 * B34 / B37) + B38), 2), 0))) -> 2.86 | C42: trips per shift | D42: DERIVED | E42: N = 8 / ((2L / S) + T) - an 8-hour shift divided by one round trip. The Trips override wins if it is filled; otherwise the Trip count basis decides whether the result keeps its decimals (CPWD) or is rounded down to a whole trip.
A43: Distance / fuel basis | B43: DIRECT ROUTE (2NL + 6) | C43: - | D43: INPUT | E43: DIRECT ROUTE computes km/day = 2NL + 6, the 6 km being the depot run - this reproduces every row of Data Sheet 1. CPWD PRO-RATA instead takes the Data Sheet 1 km/day for your lead and scales it by (your trips / the benchmark trips at that lead); that is how DAR item 1.1.18 derives 64.40 km from the 10 km row.
...

Sheet 02_Earth_Work
A1: CPWD DAR 2019 — SUB-HEAD 02: EARTH WORK (CUSTOM ITEM BUILDER)
A2: LEGEND: | B2: INPUT - you type it | C2: OVERRIDE - optional | D2: LOOKUP - fetched | E2: DERIVED - calculated | F2: RESULT - subtotal | G2: SAY - final rate | H2: CPWD rule / note | I2: Not editable
A3: CPWD DAR Sub-head 02: Earthwork operations (surface excavation, trench excavation, filling, compaction). Operates without raw material inputs, applying labour crews and earthmoving machinery hire with standard 5-step compounding statutory markups.
A4: 1. RATE ANALYSIS CONFIGURATION & OPERATIONAL PROFILE (Select parameters in D6, D7, D8, D9 to drive rate analysis)
A5: Parameter | D5: Selected Value / Parameter Input | E5: Unit | F5: Cell Role | G5: CPWD DAR 2019 Engineering Specification & Practical Field Guidance Notes
A6: Primary Work Scope | D6: Surface Excavation (≤30 cm) | E6: — | F6: INPUT | G6: Core civil work category: Surface excavation, Foundation/trenching, Embankment, Backfilling, Site clearance, Timbering, or Anti-termite.
A7: Ground Strata / Material | D7: All kinds of soil | E7: — | F7: INPUT | G7: Strata classification: All kinds of soil, Ordinary rock, Hard rock (blasting permitted), or Hard rock (blasting prohibited).
A8: Execution Method & Depth Condition | D8: Manual labor (depth ≤1.5m) | E8: — | F8: INPUT | G8: Execution technique: Manual labor (≤1.5m), Mechanical (Hydraulic Excavator 0.9 cum), Extra depth 1.5-3.0m, or Extra depth 3.0-4.5m.
A9: Operation / Task Specification | D9: General surface cut (≤30 cm deep) | E9: — | F9: INPUT | G9: Specific activity variant or application subtype (e.g. open areas, pipe trenches, post holes, tree girth band, chemical barrier stage).
A10: Standard Output Batch Quantity | D10: =IFERROR(INDEX($AC$105:$AC$153, MATCH(IF($D$9="", $D$6&"|"&$D$7&"|"&$D$8, $D$6&"|"&$D$7&"|"&$D$8&"|"&$D$9), $AA$105:$AA$153, 0)), IFERROR(INDEX($AC$105:$AC$153, MATCH($D$6&"|"&$D$7&"|"&$D$8, $AB$105:$AB$153, 0)), 100)) -> 100 | E10: units | F10: LOOKUP | G10: Standard output batch volume or area defined in CPWD DAR 2019 (100 sqm, 10 cum, 1 m, 1 tree, 10 holes).
A11: Standard Output Measurement Unit | D11: =IFERROR(INDEX($AD$105:$AD$153, MATCH(IF($D$9="", $D$6&"|"&$D$7&"|"&$D$8, $D$6&"|"&$D$7&"|"&$D$8&"|"&$D$9), $AA$105:$AA$153, 0)), IFERROR(INDEX($AD$105:$AD$153, MATCH($D$6&"|"&$D$7&"|"&$D$8, $AB$105:$AB$153, 0)), "sqm")) -> sqm | E11: — | F11: LOOKUP | G11: Billing measurement unit for work output (cum, sqm, metre, tree, hole).
A12: Custom Project Rate Reference Code | D12: C-02.01 | E12: — | F12: INPUT | G12: Project-specific non-DSR reference code when saving custom rate variations.
A13: Official Work Specification Nomenclature: | D13: =IFERROR(INDEX($AF$105:$AF$153, MATCH(IF($D$9="", $D$6&"|"&$D$7&"|"&$D$8, $D$6&"|"&$D$7&"|"&$D$8&"|"&$D$9), $AA$105:$AA$153, 0)), IFERROR(INDEX($AF$105:$AF$153, MATCH($D$6&"|"&$D$7&"|"&$D$8, $AB$105:$AB$153, 0)), "Earth Work Operation")) -> Earth work in surface excavation not exceeding 30 cm in depth but exceeding 1.5 m in width as well as 10 sqm on plan including getting out and disposal of excavated earth upto 50 m and lift upto 1.5 m, as directed by Engineer-in- Charge:: All kinds of soil Details of cost for 100 Sqm LABOUR
A14: Published Reference Say Rate (Benchmark) | D14: =IFERROR(INDEX($AE$105:$AE$153, MATCH(IF($D$9="", $D$6&"|"&$D$7&"|"&$D$8, $D$6&"|"&$D$7&"|"&$D$8&"|"&$D$9), $AA$105:$AA$153, 0)), IFERROR(INDEX($AE$105:$AE$153, MATCH($D$6&"|"&$D$7&"|"&$D$8, $AB$105:$AB$153, 0)), 92.55)) -> 92.55 | E14: =D11 -> sqm | F14: LOOKUP | G14: Official CPWD DAR 2019 Volume 1 published rate for identical scope and strata.
A15: AUDIT VERIFICATION STATUS: | D15: =IF(AND(H58<=0.05, H58>=-0.05), "[PASS] 100% DAR MATCH", "[ALERT] VARIANCE DETECTED") -> [PASS] 100% DAR MATCH | E15: Cost Base: | F15: =IF(H41>0, "OK", "ERR: W<=0") -> OK | G15: Live variance check against published CPWD DAR 2019 Volume 1 Say Rate. Target variance: ₹ 0.00.
A17: 1B. PARAMETRIC OPERATIONAL SPECIFICATION PROFILE (5 CORE CIVIL WORK LEVERS) | P17: HELPER TABLE 1B: OPERATIONAL LEVER MULTIPLIER RULES (Lookup Source for Table 2 Col Q)
A18: Operational Work Lever | D18: Active Execution Mechanism / Field Technique | E18: CPWD Standard Field Specification & Practical Engineering Scope Notes | P18: Resource Code | Q18: Resource Description & Trade Role | R18: Governing Civil Lever | S18: Active Multiplier
A19: 1. Loosening / Digging Mode | D19: =IFERROR(INDEX($AG$105:$AG$153, MATCH(IF($D$9="", $D$6&"|"&$D$7&"|"&$D$8, $D$6&"|"&$D$7&"|"&$D$8&"|"&$D$9), $AA$105:$AA$153, 0)), IFERROR(INDEX($AG$105:$AG$153, MATCH($D$6&"|"&$D$7&"|"&$D$8, $AB$105:$AB$153, 0)), "Standard Digging")) -> Manual Pickaxe / Beldar | E19: Loosening of soil/rock crust to required formation level or trench invert. | P19: 0101 | Q19: Bhishti (Compaction Watering to OMC) | R19: Lever 4: Compaction Watering ($D$22) | S19: =IF($D$22="NO", 0, 1) -> 1
A20: 2. Handling & Haulage Boundary | D20: =IFERROR(INDEX($AH$105:$AH$153, MATCH(IF($D$9="", $D$6&"|"&$D$7&"|"&$D$8, $D$6&"|"&$D$7&"|"&$D$8&"|"&$D$9), $AA$105:$AA$153, 0)), IFERROR(INDEX($AH$105:$AH$153, MATCH($D$6&"|"&$D$7&"|"&$D$8, $AB$105:$AB$153, 0)), "Standard Haulage")) -> Manual Basket (≤50m lead, ≤1.5m lift) | E20: Haulage boundary: lead up to 50 m and lift up to 1.5 m from excavation face. | P20: 0003 | Q20: 10 Tonne Road Roller (Compaction) | R20: Lever 5: Power Roller Compaction ($D$23) | S20: =IF($D$23="NO", 0, 1) -> 1
A21: 3. Layer Placement & Spreading | D21: =IFERROR(INDEX($AI$105:$AI$153, MATCH(IF($D$9="", $D$6&"|"&$D$7&"|"&$D$8, $D$6&"|"&$D$7&"|"&$D$8&"|"&$D$9), $AA$105:$AA$153, 0)), IFERROR(INDEX($AI$105:$AI$153, MATCH($D$6&"|"&$D$7&"|"&$D$8, $AB$105:$AB$153, 0)), "Standard Spreading")) -> Dressing & grading surface | E21: Depositing excavated earth in uniform layers ≤20 cm depth, breaking clods and shaping slopes. | P21: 0011 | Q21: Chowkidar (Road Roller Guard) | R21: Lever 5: Power Roller Compaction ($D$23) | S21: =IF($D$23="NO", 0, 1) -> 1
A22: 4. Compaction Watering to OMC | D22: YES | E22: =IF(ISNUMBER(SEARCH("Embankment", $D$6)), IF($D$22="YES", "Watering included in item specification (0.40 Bhishti-day / 10 cum to achieve OMC). Full rate applies.", "DEDUCTION APPLIED (DAR Item 2.5): 0.40 Bhishti-day @ Rs 617 = Rs 246.80 direct. With GST 14.05% (Rs 34.68) + CPOH 15% (Rs 42.22) + Cess 1% (Rs 3.24) = Total Rs 326.94/10 cum -> Rate reduced by Rs 33.00/cum (-Rs 32.70 exact)."), "Surface Excavation, Foundation Trenches, Jungle Clearance, Timbering Item specification does not include watering/compaction. (No deduction applicable).") -> Surface Excavation, Foundation Trenches, Jungle Clearance, Timbering Item specification does not include watering/compaction. (No deduction applicable). | P22: 0113 | Q22: Sundries (Road Roller) | R22: Lever 5: Power Roller Compaction ($D$23) | S22: =IF($D$23="NO", 0, 1) -> 1
A23: 5. Compaction Mechanism | D23: YES | E23: =IF(ISNUMBER(SEARCH("Embankment", $D$6)), IF($D$23="YES", "Power rolling included in item specification (0.008 roller-day / 10 cum). Full rate applies.", "DEDUCTION APPLIED (DAR Item 2.4): 0.008 Roller @ Rs 3000 (Rs 24.00) + 0.008 Chowkidar (Rs 4.46) + Sundries (Rs 3.64) = Rs 32.10 direct. Compounded total = Rs 42.95/10 cum -> Rate reduced by Rs 4.30/cum (-Rs 4.30 exact)."), "Surface Excavation, Foundation Trenches, Jungle Clearance, Timbering Item specification does not include watering/compaction. (No deduction applicable).") -> Surface Excavation, Foundation Trenches, Jungle Clearance, Timbering Item specification does not include watering/compaction. (No deduction applicable).
A25: 2. ACTIVE RESOURCE BUILD-UP (Auto-populated from Table 5E Ground-Truth Norms; Equipment codes include fuel & crew) | P25: HELPER TABLE 2: FIRST-PRINCIPLES QUANTITY RESOLVER (Calculates Table 2 Col F) | S25: DEDICATED ENGINEERING LOGIC, PRECEDENTS & AUDIT TABLE (Precedents, Site Mechanics & Shift Derivation)
A26: Line | B26: Resource Code | C26: Resource Name & Description | D26: Resource Category | E26: Unit | F26: Norm Input Qty | G26: Unit Rate (₹) | H26: Line Amount (₹) | I26: Include? / Apply | J26: Cost Share % | K26: Daily Productivity Norm | L26: Specific Effort | M26: Hourly Pace | N26: Field Guidance Note | O26: Engineering First-Principles & 8-Hour Shift Logic | P26: Base Physical Norm (D10 / Kr) | Q26: Lever Factor (Helper 1B Lookup) | R26: Net Calculated Quantity | S26: Governing Operational Precedent | T26: Live Precedent & Calculation Trace | U26: Engineering First-Principles (Physical Mechanics) | V26: CPWD 8-Hour Shift Logic (Mathematical Derivation) | W26: Contractual Omission & Deduction Audit Clause
A27: 1 | B27: =IFERROR(INDEX($F$105:$F$282, MATCH($D$6&"|"&$D$7&"|"&$D$8&"|"&$D$9&"|"&1, $J$105:$J$282, 0)), "") -> 0114 | C27: =IF(B27="","", IFERROR(INDEX(Rates_Master!$C:$C, MATCH(B27, Rates_Master!$A:$A, 0)), "Custom Resource")) -> Beldar | D27: =IF(B27="","", IFERROR(INDEX(Rates_Master!$B:$B, MATCH(B27, Rates_Master!$A:$A, 0)), "Labour")) -> Labour Wages | E27: =IF(B27="","", IFERROR(INDEX(Rates_Master!$D:$D, MATCH(B27, Rates_Master!$A:$A, 0)), "day")) -> day | F27: =IF(B27="","", R27) -> 6.8 | G27: =IF(B27="","", IFERROR(INDEX(Rates_Master!$E:$E, MATCH(B27, Rates_Master!$A:$A, 0)), 0)) -> 558 | H27: =IF(OR(B27="", F27=""), 0, ROUND(F27 * G27, 2)) -> 3794.4 | I27: =IF(B27="","", IF(ISNUMBER(SEARCH("2.10", B27)), "A", "W")) -> W | J27: =IF(H$41>0, ROUND(H27 / H$41 * 100, 1), 0) -> 54.8 | K27: =IFERROR(INDEX($G$105:$G$282, MATCH($D$6&"|"&$D$7&"|"&$D$8&"|"&$D$9&"|"&1, $J$105:$J$282, 0)), "") -> 14.705882 | L27: =IF(AND(ISNUMBER(F27), F27>0, D$10>0), ROUND(F27 * 8 / D$10, 4), "") -> 0.544 | M27: =IF(AND(ISNUMBER(F27), F27>0, D$10>0), ROUND(D$10 / (F27 * 8), 2), "") -> 1.84 | N27: =IF(B27="","", "CPWD Standard Earthwork Production Resource") -> CPWD Standard Earthwork Production Resource | O27: =IF(B27="","", V27) -> Gang: 4 Beldars × 13.60 h = 54.40 man-hrs ÷ 8.00 h = 6.800 Beldar-days per 100 sqm. Daily productivity norm P = 14.71 sqm/8-hr shift (SE = 0.544 hr/sqm, pace = 32.6 min/sqm). | P27: =IF(B27="","", IF(AND(ISNUMBER(K27), K27>0), ROUND(D$10/K27, 5), IFERROR(INDEX($K$105:$K$282, MATCH($D$6&"|"&$D$7&"|"&$D$8&"|"&$D$9&"|"&1, $J$105:$J$282, 0)), 0))) -> 6.8 | Q27: =IF(B27="","", IFERROR(VLOOKUP(B27, $P$19:$S$22, 4, FALSE), 1)) -> 1 | R27: =IF(B27="","", ROUND(P27 * Q27, 5)) -> 6.8 | S27: =IF(B27="","", IF(B27="0101", "Lever 4: Compaction Watering ($D$22 = " & $D$22 & ")", IF(OR(B27="0003", B27="0011", B27="0113"), "Lever 5: Power Rolling ($D$23 = " & $D$23 & ")", "Core Scope Baseline (Mandatory Execution)"))) -> Core Scope Baseline (Mandatory Execution) | T27: =IF(B27="","", "Batch Q=" & TEXT(D$10, "0.00") & " " & $D$11 & " | Norm K=" & TEXT(K27, "0.00") & " | Factor=" & TEXT(Q27, "0.00") & " | Qty F=" & TEXT(F27, "0.000") & " " & E27 & " | Rate G=Rs " & TEXT(G27, "0.00") & " | Amt H=Rs " & TEXT(H27, "0.00")) -> Batch Q=100.00 sqm | Norm K=14.71 | Factor=1.00 | Qty F=6.800 day | Rate G=Rs 558.00 | Amt H=Rs 3794.40 | U27: =IF(B27="","", IFERROR(INDEX($H$105:$H$282, MATCH($D$6&"|"&$D$7&"|"&$D$8&"|"&$D$9&"|"&1, $J$105:$J$282, 0)), "")) -> Manual pickaxe and phowrah loosening of hard dry soil crust up to 30 cm depth, spade trimming to formation level, and clod pulverization. | V27: =IF(B27="","", IFERROR(INDEX($I$105:$I$282, MATCH($D$6&"|"&$D$7&"|"&$D$8&"|"&$D$9&"|"&1, $J$105:$J$282, 0)), "")) -> Gang: 4 Beldars × 13.60 h = 54.40 man-hrs ÷ 8.00 h = 6.800 Beldar-days per 100 sqm. Daily productivity norm P = 14.71 sqm/8-hr shift (SE = 0.544 hr/sqm, pace = 32.6 min/sqm). | W27: =IF(B27="","", IF(B27="0101", IF($D$22="NO", "OMITTED DEDUCTION (DAR Item 2.5): 0.40 Bhishti @ Rs 617 = Rs 246.80 direct. Compounded total = Rs 326.94/10 cum -> Rate deduction Rs 33.00/cum.", "ACTIVE: Compaction watering included in standard item scope."), IF(OR(B27="0003", B27="0011", B27="0113"), IF($D$23="NO", "OMITTED DEDUCTION (DAR Item 2.4): 0.008 Roller + Chowkidar + Sundries = Rs 32.10 direct. Compounded total = Rs 42.95/10 cum -> Rate deduction Rs 4.30/cum.", "ACTIVE: Power rolling included in standard item scope."), "MANDATORY: Not subject to omission or separate deduction."))) -> MANDATORY: Not subject to omission or separate deduction.
