Workbook

Sheet Rates_Master
A1: Code | B1: Category | C1: Description | D1: Unit | E1: Basic Rate (Rs)
A2: 0114 | B2: Labour | C2: Beldar | D2: day | E2: 558
A3: 0115 | B3: Labour | C3: Coolie | D3: day | E3: 558
A4: 0101 | B4: Labour | C4: Bhisti | D4: day | E4: 617
A5: 0113 | B5: Sundries | C5: Chowkidar | D5: day | E5: 558
A6: 0003 | B6: Plant | C6: Hire charges of Diesel Road Roller | D6: day | E6: 3000
A7: 9999 | B7: Sundries | C7: Sundries | D7: L.S. | E7: 2

Sheet Global_Factors
A1: GF_1 | B1: desc | C1: 0.01 | D1: unit | E1: 0.01 | F1: 0.01
A2: GF_2 | B2: desc | C2: 0.01 | D2: unit | E2: 0.01 | F2: 0.01
A3: GF_3 | B3: desc | C3: 0.01 | D3: unit | E3: 0.01 | F3: 0.01
A4: GF_4 | B4: desc | C4: 0.01 | D4: unit | E4: 0.01 | F4: 0.01
A5: GF_5 | B5: desc | C5: 0.01 | D5: unit | E5: 0.01 | F5: 0.01
A6: GF_6 | B6: desc | C6: 0.01 | D6: unit | E6: 0.01 | F6: 0.01
A7: GF_7 | B7: desc | C7: 0.01 | D7: unit | E7: 0.01 | F7: 0.01
A8: GF_8 | B8: desc | C8: 0.01 | D8: unit | E8: 0.01 | F8: 0.01
A9: GF_9 | B9: desc | C9: 0.01 | D9: unit | E9: 0.01 | F9: 0.01
A10: GF_10 | B10: desc | C10: 0.01 | D10: unit | E10: 0.01 | F10: 0.01
A11: GF_11 | B11: desc | C11: 0.01 | D11: unit | E11: 0.01 | F11: 0.01
A12: GF_12 | B12: desc | C12: 0.01 | D12: unit | E12: 0.01 | F12: 0.01
... A19: GF_19 | B19: desc | C19: 0.01 | D19: unit | E19: 0.01 | F19: 0.01

Sheet 02_Earth_Work
A1: CPWD DAR 2019 — SUB-HEAD 02: EARTH WORK (CUSTOM ITEM BUILDER)
A2: LEGEND: | B2: INPUT - you type it | C2: OVERRIDE - optional | D2: LOOKUP - fetched | E2: DERIVED - calculated | F2: RESULT - subtotal | G2: SAY - final rate | H2: CPWD rule / note | I2: Not editable
A3: CPWD DAR Sub-head 02: Earthwork operations (surface excavation, trench excavation, filling, compaction). Operates without raw material inputs, applying labour crews and earthmoving machinery hire with standard 5-step compounding statutory markups.
A4: 1. RATE ANALYSIS CONFIGURATION & OPERATIONAL PROFILE (Select parameters in D6, D7, D8, D9 to drive rate analysis)
A5: Parameter | D5: Selected Value / Parameter Input | E5: Unit | F5: Cell Role | G5: CPWD DAR 2019 Engineering Specification & Practical Field Guidance Notes
A6: Primary Work Scope | D6: Surface Excavation (≤30 cm) | E6: — | F6: INPUT | G6: Core civil work category: Surface excavation, Foundation/trenching, Embankment, Backfilling, Site clearance, Timbering, or Anti-termite.
A7: Ground Strata / Material | D7: All kinds of soil | E7: — | F7: INPUT | G7: Strata classification: All kinds of soil, Ordinary rock, Hard rock (blasting permitted), or Hard rock (blasting prohibited).
A8: Execution Method & Depth Condition | D8: Manual labor (depth ≤1.5m) | E8: — | F8: INPUT | G8: Execution technique: Manual labor (≤1.5m), Mechanical (Hydraulic Excavator 0.9 cum), Extra depth 1.5-3.0m, or Extra depth 3.0-4.5m.
A9: Operation / Task Specification | D9: General surface cut (≤30 cm deep) | E9: — | F9: INPUT | G9: Specific activity variant or application subtype (e.g. open areas, pipe trenches, post holes, tree girth band, chemical barrier stage).
A10: Standard Output Batch Quantity | D10: 1 | E10: units | F10: LOOKUP | G10: Standard output batch volume or area defined in CPWD DAR 2019 (100 sqm, 10 cum, 1 m, 1 tree, 10 holes).
A11: Standard Output Measurement Unit | D11: 1 | E11: — | F11: LOOKUP | G11: Billing measurement unit for work output (cum, sqm, metre, tree, hole).
A12: Custom Project Rate Reference Code | D12: C-02.01 | E12: — | F12: INPUT | G12: Project-specific non-DSR reference code when saving custom rate variations.
A13: Official Work Specification Nomenclature: | D13: 1
A14: Published Reference Say Rate (Benchmark) | D14: 1 | E14: 1 | F14: LOOKUP | G14: Official CPWD DAR 2019 Volume 1 published rate for identical scope and strata.
A15: AUDIT VERIFICATION STATUS: | D15: 1 | E15: Cost Base: | F15: 1 | G15: Live variance check against published CPWD DAR 2019 Volume 1 Say Rate. Target variance: ₹ 0.00.
A17: 1B. PARAMETRIC OPERATIONAL SPECIFICATION PROFILE (5 CORE CIVIL WORK LEVERS)
A18: Operational Work Lever | D18: Active Execution Mechanism / Field Technique | E18: CPWD Standard Field Specification & Practical Engineering Scope Notes
A19: 1. Loosening / Digging Mode | D19: 1 | E19: Loosening of soil/rock crust to required formation level or trench invert.
A20: 2. Handling & Haulage Boundary | D20: 1 | E20: Haulage boundary: lead up to 50 m and lift up to 1.5 m from excavation face.
A21: 3. Layer Placement & Spreading | D21: 1 | E21: Depositing excavated earth in uniform layers ≤20 cm depth, breaking clods and shaping slopes.
A22: 4. Compaction Watering to OMC | D22: YES | E22: 1
A23: 5. Compaction Mechanism | D23: YES | E23: 1
A25: 2. ACTIVE RESOURCE BUILD-UP (Auto-populated from Table 5E Ground-Truth Norms; Equipment codes include fuel & crew)
A26: Line | B26: Resource Code | C26: Resource Name & Description | D26: Resource Category | E26: Unit | F26: Norm Input Qty | G26: Unit Rate (₹) | H26: Line Amount (₹) | I26: Include? / Apply | J26: Cost Share % | K26: Daily Productivity Norm | L26: Specific Effort | M26: Hourly Pace | N26: Field Guidance Note | O26: Engineering First-Principles & 8-Hour Shift Logic
A27: 1 | B27: =IFERROR(INDEX($G$105:$G$282, MATCH($D$6&"|"&$D$7&"|"&$D$8&"|"&$D$9&"|"&1, $P$105:$P$282, 0)), "") | C27: =IF(B27="","", IFERROR(INDEX(Rates_Master!$C:$C, MATCH(B27, Rates_Master!$A:$A, 0)), IFERROR(INDEX($H$105:$H$282, MATCH($D$6&"|"&$D$7&"|"&$D$8&"|"&$D$9&"|"&1, $P$105:$P$282, 0)), "Custom Resource"))) | D27: =IF(B27="","", IFERROR(INDEX(Rates_Master!$B:$B, MATCH(B27, Rates_Master!$A:$A, 0)), "Labour")) | E27: =IF(B27="","", IFERROR(INDEX(Rates_Master!$D:$D, MATCH(B27, Rates_Master!$A:$A, 0)), "day")) | F27: =IF(B27="","", IF(B27="0101", IF($D$22="NO", 0, IF(AND(ISNUMBER(K27), K27>0), ROUND(D$10/K27, 5), IFERROR(INDEX($I$105:$I$282, MATCH($D$6&"|"&$D$7&"|"&$D$8&"|"&$D$9&"|"&1, $P$105:$P$282, 0)), 0))), IF(OR(B27="0003", B27="0011", B27="0113"), IF($D$23="NO", 0, IF(AND(ISNUMBER(K27), K27>0), ROUND(D$10/K27, 5), IFERROR(INDEX($I$105:$I$282, MATCH($D$6&"|"&$D$7&"|"&$D$8&"|"&$D$9&"|"&1, $P$105:$P$282, 0)), 0))), IF(AND(ISNUMBER(K27), K27>0), ROUND(D$10/K27, 5), IFERROR(INDEX($I$105:$I$282, MATCH($D$6&"|"&$D$7&"|"&$D$8&"|"&$D$9&"|"&1, $P$105:$P$282, 0)), 0))))) | G27: =IF(B27="","", IFERROR(INDEX(Rates_Master!$E:$E, MATCH(B27, Rates_Master!$A:$A, 0)), IFERROR(INDEX($K$105:$K$282, MATCH($D$6&"|"&$D$7&"|"&$D$8&"|"&$D$9&"|"&1, $P$105:$P$282, 0)), 0))) | H27: =IF(OR(B27="", F27=""), 0, ROUND(F27 * G27, 2)) | I27: =IF(B27="","", IF(ISNUMBER(SEARCH("2.10", B27)), "A", "W")) | J27: =IF(H$41>0, ROUND(H27 / H$41 * 100, 1), 0) | K27: =IFERROR(INDEX($N$105:$N$282, MATCH($D$6&"|"&$D$7&"|"&$D$8&"|"&$D$9&"|"&1, $P$105:$P$282, 0)), "") | L27: =IF(AND(ISNUMBER(F27), F27>0, D$10>0), ROUND(F27 * 8 / D$10, 4), "") | M27: =IF(AND(ISNUMBER(F27), F27>0, D$10>0), ROUND(D$10 / (F27 * 8), 2), "") | N27: =IF(B27="","", "CPWD Standard Earthwork Production Resource") | O27: =IF(B27="","", IF(B27="0101", IF($D$22="NO", "OMITTED DEDUCTION (DAR Item 2.5): 0.40 Bhishti-day @ Rs 617 = Rs 246.80 direct. Compounded with GST 14.05% (Rs 34.68) + CPOH 15% (Rs 42.22) + Cess 1% (Rs 3.24) = Rs 326.94/10 cum -> -Rs 33.00/cum deduction.", "Watering by Bhishti to OMC: 25 cum/8-hr day (0.40 day/10 cum)."), IF(OR(B27="0003", B27="0011", B27="0113"), IF($D$23="NO", "OMITTED DEDUCTION (DAR Item 2.4): 0.008 Roller @ Rs 3000 (Rs 24.00) + 0.008 Chowkidar (Rs 4.46) + Sundries (Rs 3.64) = Rs 32.10 direct. Compounded with Water 1% (Rs 0.32) + GST 14.05% (Rs 4.55) + CPOH 15% (Rs 5.55) + Cess 1% (Rs 0.43) = Rs 42.95/10 cum -> -Rs 4.30/cum deduction.", "Power roller compaction: 1250 cum/8-hr day (0.008 day/10 cum)."), IFERROR(INDEX($O$105:$O$282, MATCH($D$6&"|"&$D$7&"|"&$D$8&"|"&$D$9&"|"&1, $P$105:$P$282, 0)), ""))))
A28: 2 | B28: =IFERROR(INDEX($G$105:$G$282, MATCH($D$6&"|"&$D$7&"|"&$D$8&"|"&$D$9&"|"&2, $P$105:$P$282, 0)), "") | C28: =IF(B28="","", IFERROR(INDEX(Rates_Master!$C:$C, MATCH(B28, Rates_Master!$A:$A, 0)), IFERROR(INDEX($H$105:$H$282, MATCH($D$6&"|"&$D$7&"|"&$D$8&"|"&$D$9&"|"&2, $P$105:$P$282, 0)), "Custom Resource"))) | D28: =IF(B28="","", IFERROR(INDEX(Rates_Master!$B:$B, MATCH(B28, Rates_Master!$A:$A, 0)), "Labour")) | E28: =IF(B28="","", IFERROR(INDEX(Rates_Master!$D:$D, MATCH(B28, Rates_Master!$A:$A, 0)), "day")) | F28: =IF(B28="","", IF(B28="0101", IF($D$22="NO", 0, IF(AND(ISNUMBER(K28), K28>0), ROUND(D$10/K28, 5), IFERROR(INDEX($I$105:$I$282, MATCH($D$6&"|"&$D$7&"|"&$D$8&"|"&$D$9&"|"&2, $P$105:$P$282, 0)), 0))), IF(OR(B28="0003", B28="0011", B28="0113"), IF($D$23="NO", 0, IF(AND(ISNUMBER(K28), K28>0), ROUND(D$10/K28, 5), IFERROR(INDEX($I$105:$I$282, MATCH($D$6&"|"&$D$7&"|"&$D$8&"|"&$D$9&"|"&2, $P$105:$P$282, 0)), 0))), IF(AND(ISNUMBER(K28), K28>0), ROUND(D$10/K28, 5), IFERROR(INDEX($I$105:$I$282, MATCH($D$6&"|"&$D$7&"|"&$D$8&"|"&$D$9&"|"&2, $P$105:$P$282, 0)), 0))))) | G28: =IF(B28="","", IFERROR(INDEX(Rates_Master!$E:$E, MATCH(B28, Rates_Master!$A:$A, 0)), IFERROR(INDEX($K$105:$K$282, MATCH($D$6&"|"&$D$7&"|"&$D$8&"|"&$D$9&"|"&2, $P$105:$P$282, 0)), 0))) | H28: =IF(OR(B28="", F28=""), 0, ROUND(F28 * G28, 2)) | I28: =IF(B28="","", IF(ISNUMBER(SEARCH("2.10", B28)), "A", "W")) | J28: =IF(H$41>0, ROUND(H28 / H$41 * 100, 1), 0) | K28: =IFERROR(INDEX($N$105:$N$282, MATCH($D$6&"|"&$D$7&"|"&$D$8&"|"&$D$9&"|"&2, $P$105:$P$282, 0)), "") | L28: =IF(AND(ISNUMBER(F28), F28>0, D$10>0), ROUND(F28 * 8 / D$10, 4), "") | M28: =IF(AND(ISNUMBER(F28), F28>0, D$10>0), ROUND(D$10 / (F28 * 8), 2), "") | N28: =IF(B28="","", "CPWD Standard Earthwork Production Resource") | O28: =IF(B28="","", IF(B28="0101", IF($D$22="NO", "OMITTED DEDUCTION (DAR Item 2.5): 0.40 Bhishti-day @ Rs 617 = Rs 246.80 direct. Compounded with GST 14.05% (Rs 34.68) + CPOH 15% (Rs 42.22) + Cess 1% (Rs 3.24) = Rs 326.94/10 cum -> -Rs 33.00/cum deduction.", "Watering by Bhishti to OMC: 25 cum/8-hr day (0.40 day/10 cum)."), IF(OR(B28="0003", B28="0011", B28="0113"), IF($D$23="NO", "OMITTED DEDUCTION (DAR Item 2.4): 0.008 Roller @ Rs 3000 (Rs 24.00) + 0.008 Chowkidar (Rs 4.46) + Sundries (Rs 3.64) = Rs 32.10 direct. Compounded with Water 1% (Rs 0.32) + GST 14.05% (Rs 4.55) + CPOH 15% (Rs 5.55) + Cess 1% (Rs 0.43) = Rs 42.95/10 cum -> -Rs 4.30/cum deduction.", "Power roller compaction: 1250 cum/8-hr day (0.008 day/10 cum)."), IFERROR(INDEX($O$105:$O$282, MATCH($D$6&"|"&$D$7&"|"&$D$8&"|"&$D$9&"|"&2, $P$105:$P$282, 0)), ""))))
A29: 3 | B29: =IFERROR(INDEX($G$105:$G$282, MATCH($D$6&"|"&$D$7&"|"&$D$8&"|"&$D$9&"|"&3, $P$105:$P$282, 0)), "") | C29: =IF(B29="","", IFERROR(INDEX(Rates_Master!$C:$C, MATCH(B29, Rates_Master!$A:$A, 0)), IFERROR(INDEX($H$105:$H$282, MATCH($D$6&"|"&$D$7&"|"&$D$8&"|"&$D$9&"|"&3, $P$105:$P$282, 0)), "Custom Resource"))) | D29: =IF(B29="","", IFERROR(INDEX(Rates_Master!$B:$B, MATCH(B29, Rates_Master!$A:$A, 0)), "Labour")) | E29: =IF(B29="","", IFERROR(INDEX(Rates_Master!$D:$D, MATCH(B29, Rates_Master!$A:$A, 0)), "day")) | F29: =IF(B29="","", IF(B29="0101", IF($D$22="NO", 0, IF(AND(ISNUMBER(K29), K29>0), ROUND(D$10/K29, 5), IFERROR(INDEX($I$105:$I$282, MATCH($D$6&"|"&$D$7&"|"&$D$8&"|"&$D$9&"|"&3, $P$105:$P$282, 0)), 0))), IF(OR(B29="0003", B29="0011", B29="0113"), IF($D$23="NO", 0, IF(AND(ISNUMBER(K29), K29>0), ROUND(D$10/K29, 5), IFERROR(INDEX($I$105:$I$282, MATCH($D$6&"|"&$D$7&"|"&$D$8&"|"&$D$9&"|"&3, $P$105:$P$282, 0)), 0))), IF(AND(ISNUMBER(K29), K29>0), ROUND(D$10/K29, 5), IFERROR(INDEX($I$105:$I$282, MATCH($D$6&"|"&$D$7&"|"&$D$8&"|"&$D$9&"|"&3, $P$105:$P$282, 0)), 0))))) | G29: =IF(B29="","", IFERROR(INDEX(Rates_Master!$E:$E, MATCH(B29, Rates_Master!$A:$A, 0)), IFERROR(INDEX($K$105:$K$282, MATCH($D$6&"|"&$D$7&"|"&$D$8&"|"&$D$9&"|"&3, $P$105:$P$282, 0)), 0))) | H29: =IF(OR(B29="", F29=""), 0, ROUND(F29 * G29, 2)) | I29: =IF(B29="","", IF(ISNUMBER(SEARCH("2.10", B29)), "A", "W")) | J29: =IF(H$41>0, ROUND(H29 / H$41 * 100, 1), 0) | K29: =IFERROR(INDEX($N$105:$N$282, MATCH($D$6&"|"&$D$7&"|"&$D$8&"|"&$D$9&"|"&3, $P$105:$P$282, 0)), "") | L29: =IF(AND(ISNUMBER(F29), F29>0, D$10>0), ROUND(F29 * 8 / D$10, 4), "") | M29: =IF(AND(ISNUMBER(F29), F29>0, D$10>0), ROUND(D$10 / (F29 * 8), 2), "") | N29: =IF(B29="","", "CPWD Standard Earthwork Production Resource") | O29: =IF(B29="","", IF(B29="0101", IF($D$22="NO", "OMITTED DEDUCTION (DAR Item 2.5): 0.40 Bhishti-day @ Rs 617 = Rs 246.80 direct. Compounded with GST 14.05% (Rs 34.68) + CPOH 15% (Rs 42.22) + Cess 1% (Rs 3.24) = Rs 326.94/10 cum -> -Rs 33.00/cum deduction.", "Watering by Bhishti to OMC: 25 cum/8-hr day (0.40 day/10 cum)."), IF(OR(B29="0003", B29="0011", B29="0113"), IF($D$23="NO", "OMITTED DEDUCTION (DAR Item 2.4): 0.008 Roller @ Rs 3000 (Rs 24.00) + 0.008 Chowkidar (Rs 4.46) + Sundries (Rs 3.64) = Rs 32.10 direct. Compounded with Water 1% (Rs 0.32) + GST 14.05% (Rs 4.55) + CPOH 15% (Rs 5.55) + Cess 1% (Rs 0.43) = Rs 42.95/10 cum -> -Rs 4.30/cum deduction.", "Power roller compaction: 1250 cum/8-hr day (0.008 day/10 cum)."), IFERROR(INDEX($O$105:$O$282, MATCH($D$6&"|"&$D$7&"|"&$D$8&"|"&$D$9&"|"&3, $P$105:$P$282, 0)), ""))))
A30: 4 | B30: =IFERROR(INDEX($G$105:$G$282, MATCH($D$6&"|"&$D$7&"|"&$D$8&"|"&$D$9&"|"&4, $P$105:$P$282, 0)), "") | C30: =IF(B30="","", IFERROR(INDEX(Rates_Master!$C:$C, MATCH(B30, Rates_Master!$A:$A, 0)), IFERROR(INDEX($H$105:$H$282, MATCH($D$6&"|"&$D$7&"|"&$D$8&"|"&$D$9&"|"&4, $P$105:$P$282, 0)), "Custom Resource"))) | D30: =IF(B30="","", IFERROR(INDEX(Rates_Master!$B:$B, MATCH(B30, Rates_Master!$A:$A, 0)), "Labour")) | E30: =IF(B30="","", IFERROR(INDEX(Rates_Master!$D:$D, MATCH(B30, Rates_Master!$A:$A, 0)), "day")) | F30: =IF(B30="","", IF(B30="0101", IF($D$22="NO", 0, IF(AND(ISNUMBER(K30), K30>0), ROUND(D$10/K30, 5), IFERROR(INDEX($I$105:$I$282, MATCH($D$6&"|"&$D$7&"|"&$D$8&"|"&$D$9&"|"&4, $P$105:$P$282, 0)), 0))), IF(OR(B30="0003", B30="0011", B30="0113"), IF($D$23="NO", 0, IF(AND(ISNUMBER(K30), K30>0), ROUND(D$10/K30, 5), IFERROR(INDEX($I$105:$I$282, MATCH($D$6&"|"&$D$7&"|"&$D$8&"|"&$D$9&"|"&4, $P$105:$P$282, 0)), 0))), IF(AND(ISNUMBER(K30), K30>0), ROUND(D$10/K30, 5), IFERROR(INDEX($I$105:$I$282, MATCH($D$6&"|"&$D$7&"|"&$D$8&"|"&$D$9&"|"&4, $P$105:$P$282, 0)), 0))))) | G30: =IF(B30="","", IFERROR(INDEX(Rates_Master!$E:$E, MATCH(B30, Rates_Master!$A:$A, 0)), IFERROR(INDEX($K$105:$K$282, MATCH($D$6&"|"&$D$7&"|"&$D$8&"|"&$D$9&"|"&4, $P$105:$P$282, 0)), 0))) | H30: =IF(OR(B30="", F30=""), 0, ROUND(F30 * G30, 2)) | I30: =IF(B30="","", IF(ISNUMBER(SEARCH("2.10", B30)), "A", "W")) | J30: =IF(H$41>0, ROUND(H30 / H$41 * 100, 1), 0) | K30: =IFERROR(INDEX($N$105:$N$282, MATCH($D$6&"|"&$D$7&"|"&$D$8&"|"&$D$9&"|"&4, $P$105:$P$282, 0)), "") | L30: =IF(AND(ISNUMBER(F30), F30>0, D$10>0), ROUND(F30 * 8 / D$10, 4), "") | M30: =IF(AND(ISNUMBER(F30), F30>0, D$10>0), ROUND(D$10 / (F30 * 8), 2), "") | N30: =IF(B30="","", "CPWD Standard Earthwork Production Resource") | O30: =IF(B30="","", IF(B30="0101", IF($D$22="NO", "OMITTED DEDUCTION (DAR Item 2.5): 0.40 Bhishti-day @ Rs 617 = Rs 246.80 direct. Compounded with GST 14.05% (Rs 34.68) + CPOH 15% (Rs 42.22) + Cess 1% (Rs 3.24) = Rs 326.94/10 cum -> -Rs 33.00/cum deduction.", "Watering by Bhishti to OMC: 25 cum/8-hr day (0.40 day/10 cum)."), IF(OR(B30="0003", B30="0011", B30="0113"), IF($D$23="NO", "OMITTED DEDUCTION (DAR Item 2.4): 0.008 Roller @ Rs 3000 (Rs 24.00) + 0.008 Chowkidar (Rs 4.46) + Sundries (Rs 3.64) = Rs 32.10 direct. Compounded with Water 1% (Rs 0.32) + GST 14.05% (Rs 4.55) + CPOH 15% (Rs 5.55) + Cess 1% (Rs 0.43) = Rs 42.95/10 cum -> -Rs 4.30/cum deduction.", "Power roller compaction: 1250 cum/8-hr day (0.008 day/10 cum)."), IFERROR(INDEX($O$105:$O$282, MATCH($D$6&"|"&$D$7&"|"&$D$8&"|"&$D$9&"|"&4, $P$105:$P$282, 0)), ""))))
A31: 5 | B31: =IFERROR(INDEX($G$105:$G$282, MATCH($D$6&"|"&$D$7&"|"&$D$8&"|"&$D$9&"|"&5, $P$105:$P$282, 0)), "") | C31: =IF(B31="","", IFERROR(INDEX(Rates_Master!$C:$C, MATCH(B31, Rates_Master!$A:$A, 0)), IFERROR(INDEX($H$105:$H$282, MATCH($D$6&"|"&$D$7&"|"&$D$8&"|"&$D$9&"|"&5, $P$105:$P$282, 0)), "Custom Resource"))) | D31: =IF(B31="","", IFERROR(INDEX(Rates_Master!$B:$B, MATCH(B31, Rates_Master!$A:$A, 0)), "Labour")) | E31: =IF(B31="","", IFERROR(INDEX(Rates_Master!$D:$D, MATCH(B31, Rates_Master!$A:$A, 0)), "day")) | F31: =IF(B31="","", IF(B31="0101", IF($D$22="NO", 0, IF(AND(ISNUMBER(K31), K31>0), ROUND(D$10/K31, 5), IFERROR(INDEX($I$105:$I$282, MATCH($D$6&"|"&$D$7&"|"&$D$8&"|"&$D$9&"|"&5, $P$105:$P$282, 0)), 0))), IF(OR(B31="0003", B31="0011", B31="0113"), IF($D$23="NO", 0, IF(AND(ISNUMBER(K31), K31>0), ROUND(D$10/K31, 5), IFERROR(INDEX($I$105:$I$282, MATCH($D$6&"|"&$D$7&"|"&$D$8&"|"&$D$9&"|"&5, $P$105:$P$282, 0)), 0))), IF(AND(ISNUMBER(K31), K31>0), ROUND(D$10/K31, 5), IFERROR(INDEX($I$105:$I$282, MATCH($D$6&"|"&$D$7&"|"&$D$8&"|"&$D$9&"|"&5, $P$105:$P$282, 0)), 0))))) | G31: =IF(B31="","", IFERROR(INDEX(Rates_Master!$E:$E, MATCH(B31, Rates_Master!$A:$A, 0)), IFERROR(INDEX($K$105:$K$282, MATCH($D$6&"|"&$D$7&"|"&$D$8&"|"&$D$9&"|"&5, $P$105:$P$282, 0)), 0))) | H31: =IF(OR(B31="", F31=""), 0, ROUND(F31 * G31, 2)) | I31: =IF(B31="","", IF(ISNUMBER(SEARCH("2.10", B31)), "A", "W")) | J31: =IF(H$41>0, ROUND(H31 / H$41 * 100, 1), 0) | K31: =IFERROR(INDEX($N$105:$N$282, MATCH($D$6&"|"&$D$7&"|"&$D$8&"|"&$D$9&"|"&5, $P$105:$P$282, 0)), "") | L31: =IF(AND(ISNUMBER(F31), F31>0, D$10>0), ROUND(F31 * 8 / D$10, 4), "") | M31: =IF(AND(ISNUMBER(F31), F31>0, D$10>0), ROUND(D$10 / (F31 * 8), 2), "") | N31: =IF(B31="","", "CPWD Standard Earthwork Production Resource") | O31: =IF(B31="","", IF(B31="0101", IF($D$22="NO", "OMITTED DEDUCTION (DAR Item 2.5): 0.40 Bhishti-day @ Rs 617 = Rs 246.80 direct. Compounded with GST 14.05% (Rs 34.68) + CPOH 15% (Rs 42.22) + Cess 1% (Rs 3.24) = Rs 326.94/10 cum -> -Rs 33.00/cum deduction.", "Watering by Bhishti to OMC: 25 cum/8-hr day (0.40 day/10 cum)."), IF(OR(B31="0003", B31="0011", B31="0113"), IF($D$23="NO", "OMITTED DEDUCTION (DAR Item 2.4): 0.008 Roller @ Rs 3000 (Rs 24.00) + 0.008 Chowkidar (Rs 4.46) + Sundries (Rs 3.64) = Rs 32.10 direct. Compounded with Water 1% (Rs 0.32) + GST 14.05% (Rs 4.55) + CPOH 15% (Rs 5.55) + Cess 1% (Rs 0.43) = Rs 42.95/10 cum -> -Rs 4.30/cum deduction.", "Power roller compaction: 1250 cum/8-hr day (0.008 day/10 cum)."), IFERROR(INDEX($O$105:$O$282, MATCH($D$6&"|"&$D$7&"|"&$D$8&"|"&$D$9&"|"&5, $P$105:$P$282, 0)), ""))))
A32: 6 | B32: =IFERROR(INDEX($G$105:$G$282, MATCH($D$6&"|"&$D$7&"|"&$D$8&"|"&$D$9&"|"&6, $P$105:$P$282, 0)), "") | C32: =IF(B32="","", IFERROR(INDEX(Rates_Master!$C:$C, MATCH(B32, Rates_Master!$A:$A, 0)), IFERROR(INDEX($H$105:$H$282, MATCH($D$6&"|"&$D$7&"|"&$D$8&"|"&$D$9&"|"&6, $P$105:$P$282, 0)), "Custom Resource"))) | D32: =IF(B32="","", IFERROR(INDEX(Rates_Master!$B:$B, MATCH(B32, Rates_Master!$A:$A, 0)), "Labour")) | E32: =IF(B32="","", IFERROR(INDEX(Rates_Master!$D:$D, MATCH(B32, Rates_Master!$A:$A, 0)), "day")) | F32: =IF(B32="","", IF(B32="0101", IF($D$22="NO", 0, IF(AND(ISNUMBER(K32), K32>0), ROUND(D$10/K32, 5), IFERROR(INDEX($I$105:$I$282, MATCH($D$6&"|"&$D$7&"|"&$D$8&"|"&$D$9&"|"&6, $P$105:$P$282, 0)), 0))), IF(OR(B32="0003", B32="0011", B32="0113"), IF($D$23="NO", 0, IF(AND(ISNUMBER(K32), K32>0), ROUND(D$10/K32, 5), IFERROR(INDEX($I$105:$I$282, MATCH($D$6&"|"&$D$7&"|"&$D$8&"|"&$D$9&"|"&6, $P$105:$P$282, 0)), 0))), IF(AND(ISNUMBER(K32), K32>0), ROUND(D$10/K32, 5), IFERROR(INDEX($I$105:$I$282, MATCH($D$6&"|"&$D$7&"|"&$D$8&"|"&$D$9&"|"&6, $P$105:$P$282, 0)), 0))))) | G32: =IF(B32="","", IFERROR(INDEX(Rates_Master!$E:$E, MATCH(B32, Rates_Master!$A:$A, 0)), IFERROR(INDEX($K$105:$K$282, MATCH($D$6&"|"&$D$7&"|"&$D$8&"|"&$D$9&"|"&6, $P$105:$P$282, 0)), 0))) | H32: =IF(OR(B32="", F32=""), 0, ROUND(F32 * G32, 2)) | I32: =IF(B32="","", IF(ISNUMBER(SEARCH("2.10", B32)), "A", "W")) | J32: =IF(H$41>0, ROUND(H32 / H$41 * 100, 1), 0) | K32: =IFERROR(INDEX($N$105:$N$282, MATCH($D$6&"|"&$D$7&"|"&$D$8&"|"&$D$9&"|"&6, $P$105:$P$282, 0)), "") | L32: =IF(AND(ISNUMBER(F32), F32>0, D$10>0), ROUND(F32 * 8 / D$10, 4), "") | M32: =IF(AND(ISNUMBER(F32), F32>0, D$10>0), ROUND(D$10 / (F32 * 8), 2), "") | N32: =IF(B32="","", "CPWD Standard Earthwork Production Resource") | O32: =IF(B32="","", IF(B32="0101", IF($D$22="NO", "OMITTED DEDUCTION (DAR Item 2.5): 0.40 Bhishti-day @ Rs 617 = Rs 246.80 direct. Compounded with GST 14.05% (Rs 34.68) + CPOH 15% (Rs 42.22) + Cess 1% (Rs 3.24) = Rs 326.94/10 cum -> -Rs 33.00/cum deduction.", "Watering by Bhishti to OMC: 25 cum/8-hr day (0.40 day/10 cum)."), IF(OR(B32="0003", B32="0011", B32="0113"), IF($D$23="NO", "OMITTED DEDUCTION (DAR Item 2.4): 0.008 Roller @ Rs 3000 (Rs 24.00) + 0.008 Chowkidar (Rs 4.46) + Sundries (Rs 3.64) = Rs 32.10 direct. Compounded with Water 1% (Rs 0.32) + GST 14.05% (Rs 4.55) + CPOH 15% (Rs 5.55) + Cess 1% (Rs 0.43) = Rs 42.95/10 cum -> -Rs 4.30/cum deduction.", "Power roller compaction: 1250 cum/8-hr day (0.008 day/10 cum)."), IFERROR(INDEX($O$105:$O$282, MATCH($D$6&"|"&$D$7&"|"&$D$8&"|"&$D$9&"|"&6, $P$105:$P$282, 0)), ""))))
A33: 7 | B33: =IFERROR(INDEX($G$105:$G$282, MATCH($D$6&"|"&$D$7&"|"&$D$8&"|"&$D$9&"|"&7, $P$105:$P$282, 0)), "") | C33: =IF(B33="","", IFERROR(INDEX(Rates_Master!$C:$C, MATCH(B33, Rates_Master!$A:$A, 0)), IFERROR(INDEX($H$105:$H$282, MATCH($D$6&"|"&$D$7&"|"&$D$8&"|"&$D$9&"|"&7, $P$105:$P$282, 0)), "Custom Resource"))) | D33: =IF(B33="","", IFERROR(INDEX(Rates_Master!$B:$B, MATCH(B33, Rates_Master!$A:$A, 0)), "Labour")) | E33: =IF(B33="","", IFERROR(INDEX(Rates_Master!$D:$D, MATCH(B33, Rates_Master!$A:$A, 0)), "day")) | F33: =IF(B33="","", IF(B33="0101", IF($D$22="NO", 0, IF(AND(ISNUMBER(K33), K33>0), ROUND(D$10/K33, 5), IFERROR(INDEX($I$105:$I$282, MATCH($D$6&"|"&$D$7&"|"&$D$8&"|"&$D$9&"|"&7, $P$105:$P$282, 0)), 0))), IF(OR(B33="0003", B33="0011", B33="0113"), IF($D$23="NO", 0, IF(AND(ISNUMBER(K33), K33>0), ROUND(D$10/K33, 5), IFERROR(INDEX($I$105:$I$282, MATCH($D$6&"|"&$D$7&"|"&$D$8&"|"&$D$9&"|"&7, $P$105:$P$282, 0)), 0))), IF(AND(ISNUMBER(K33), K33>0), ROUND(D$10/K33, 5), IFERROR(INDEX($I$105:$I$282, MATCH($D$6&"|"&$D$7&"|"&$D$8&"|"&$D$9&"|"&7, $P$105:$P$282, 0)), 0))))) | G33: =IF(B33="","", IFERROR(INDEX(Rates_Master!$E:$E, MATCH(B33, Rates_Master!$A:$A, 0)), IFERROR(INDEX($K$105:$K$282, MATCH($D$6&"|"&$D$7&"|"&$D$8&"|"&$D$9&"|"&7, $P$105:$P$282, 0)), 0))) | H33: =IF(OR(B33="", F33=""), 0, ROUND(F33 * G33, 2)) | I33: =IF(B33="","", IF(ISNUMBER(SEARCH("2.10", B33)), "A", "W")) | J33: =IF(H$41>0, ROUND(H33 / H$41 * 100, 1), 0) | K33: =IFERROR(INDEX($N$105:$N$282, MATCH($D$6&"|"&$D$7&"|"&$D$8&"|"&$D$9&"|"&7, $P$105:$P$282, 0)), "") | L33: =IF(AND(ISNUMBER(F33), F33>0, D$10>0), ROUND(F33 * 8 / D$10, 4), "") | M33: =IF(AND(ISNUMBER(F33), F33>0, D$10>0), ROUND(D$10 / (F33 * 8), 2), "") | N33: =IF(B33="","", "CPWD Standard Earthwork Production Resource") | O33: =IF(B33="","", IF(B33="0101", IF($D$22="NO", "OMITTED DEDUCTION (DAR Item 2.5): 0.40 Bhishti-day @ Rs 617 = Rs 246.80 direct. Compounded with GST 14.05% (Rs 34.68) + CPOH 15% (Rs 42.22) + Cess 1% (Rs 3.24) = Rs 326.94/10 cum -> -Rs 33.00/cum deduction.", "Watering by Bhishti to OMC: 25 cum/8-hr day (0.40 day/10 cum)."), IF(OR(B33="0003", B33="0011", B33="0113"), IF($D$23="NO", "OMITTED DEDUCTION (DAR Item 2.4): 0.008 Roller @ Rs 3000 (Rs 24.00) + 0.008 Chowkidar (Rs 4.46) + Sundries (Rs 3.64) = Rs 32.10 direct. Compounded with Water 1% (Rs 0.32) + GST 14.05% (Rs 4.55) + CPOH 15% (Rs 5.55) + Cess 1% (Rs 0.43) = Rs 42.95/10 cum -> -Rs 4.30/cum deduction.", "Power roller compaction: 1250 cum/8-hr day (0.008 day/10 cum)."), IFERROR(INDEX($O$105:$O$282, MATCH($D$6&"|"&$D$7&"|"&$D$8&"|"&$D$9&"|"&7, $P$105:$P$282, 0)), ""))))
A34: 8 | B34: =IFERROR(INDEX($G$105:$G$282, MATCH($D$6&"|"&$D$7&"|"&$D$8&"|"&$D$9&"|"&8, $P$105:$P$282, 0)), "") | C34: =IF(B34="","", IFERROR(INDEX(Rates_Master!$C:$C, MATCH(B34, Rates_Master!$A:$A, 0)), IFERROR(INDEX($H$105:$H$282, MATCH($D$6&"|"&$D$7&"|"&$D$8&"|"&$D$9&"|"&8, $P$105:$P$282, 0)), "Custom Resource"))) | D34: =IF(B34="","", IFERROR(INDEX(Rates_Master!$B:$B, MATCH(B34, Rates_Master!$A:$A, 0)), "Labour")) | E34: =IF(B34="","", IFERROR(INDEX(Rates_Master!$D:$D, MATCH(B34, Rates_Master!$A:$A, 0)), "day")) | F34: =IF(B34="","", IF(B34="0101", IF($D$22="NO", 0, IF(AND(ISNUMBER(K34), K34>0), ROUND(D$10/K34, 5), IFERROR(INDEX($I$105:$I$282, MATCH($D$6&"|"&$D$7&"|"&$D$8&"|"&$D$9&"|"&8, $P$105:$P$282, 0)), 0))), IF(OR(B34="0003", B34="0011", B34="0113"), IF($D$23="NO", 0, IF(AND(ISNUMBER(K34), K34>0), ROUND(D$10/K34, 5), IFERROR(INDEX($I$105:$I$282, MATCH($D$6&"|"&$D$7&"|"&$D$8&"|"&$D$9&"|"&8, $P$105:$P$282, 0)), 0))), IF(AND(ISNUMBER(K34), K34>0), ROUND(D$10/K34, 5), IFERROR(INDEX($I$105:$I$282, MATCH($D$6&"|"&$D$7&"|"&$D$8&"|"&$D$9&"|"&8, $P$105:$P$282, 0)), 0))))) | G34: =IF(B34="","", IFERROR(INDEX(Rates_Master!$E:$E, MATCH(B34, Rates_Master!$A:$A, 0)), IFERROR(INDEX($K$105:$K$282, MATCH($D$6&"|"&$D$7&"|"&$D$8&"|"&$D$9&"|"&8, $P$105:$P$282, 0)), 0))) | H34: =IF(OR(B34="", F34=""), 0, ROUND(F34 * G34, 2)) | I34: =IF(B34="","", IF(ISNUMBER(SEARCH("2.10", B34)), "A", "W")) | J34: =IF(H$41>0, ROUND(H34 / H$41 * 100, 1), 0) | K34: =IFERROR(INDEX($N$105:$N$282, MATCH($D$6&"|"&$D$7&"|"&$D$8&"|"&$D$9&"|"&8, $P$105:$P$282, 0)), "") | L34: =IF(AND(ISNUMBER(F34), F34>0, D$10>0), ROUND(F34 * 8 / D$10, 4), "") | M34: =IF(AND(ISNUMBER(F34), F34>0, D$10>0), ROUND(D$10 / (F34 * 8), 2), "") | N34: =IF(B34="","", "CPWD Standard Earthwork Production Resource") | O34: =IF(B34="","", IF(B34="0101", IF($D$22="NO", "OMITTED DEDUCTION (DAR Item 2.5): 0.40 Bhishti-day @ Rs 617 = Rs 246.80 direct. Compounded with GST 14.05% (Rs 34.68) + CPOH 15% (Rs 42.22) + Cess 1% (Rs 3.24) = Rs 326.94/10 cum -> -Rs 33.00/cum deduction.", "Watering by Bhishti to OMC: 25 cum/8-hr day (0.40 day/10 cum)."), IF(OR(B34="0003", B34="0011", B34="0113"), IF($D$23="NO", "OMITTED DEDUCTION (DAR Item 2.4): 0.008 Roller @ Rs 3000 (Rs 24.00) + 0.008 Chowkidar (Rs 4.46) + Sundries (Rs 3.64) = Rs 32.10 direct. Compounded with Water 1% (Rs 0.32) + GST 14.05% (Rs 4.55) + CPOH 15% (Rs 5.55) + Cess 1% (Rs 0.43) = Rs 42.95/10 cum -> -Rs 4.30/cum deduction.", "Power roller compaction: 1250 cum/8-hr day (0.008 day/10 cum)."), IFERROR(INDEX($O$105:$O$282, MATCH($D$6&"|"&$D$7&"|"&$D$8&"|"&$D$9&"|"&8, $P$105:$P$282, 0)), ""))))
A35: 9 | B35: =IFERROR(INDEX($G$105:$G$282, MATCH($D$6&"|"&$D$7&"|"&$D$8&"|"&$D$9&"|"&9, $P$105:$P$282, 0)), "") | C35: =IF(B35="","", IFERROR(INDEX(Rates_Master!$C:$C, MATCH(B35, Rates_Master!$A:$A, 0)), IFERROR(INDEX($H$105:$H$282, MATCH($D$6&"|"&$D$7&"|"&$D$8&"|"&$D$9&"|"&9, $P$105:$P$282, 0)), "Custom Resource"))) | D35: =IF(B35="","", IFERROR(INDEX(Rates_Master!$B:$B, MATCH(B35, Rates_Master!$A:$A, 0)), "Labour")) | E35: =IF(B35="","", IFERROR(INDEX(Rates_Master!$D:$D, MATCH(B35, Rates_Master!$A:$A, 0)), "day")) | F35: =IF(B35="","", IF(B35="0101", IF($D$22="NO", 0, IF(AND(ISNUMBER(K35), K35>0), ROUND(D$10/K35, 5), IFERROR(INDEX($I$105:$I$282, MATCH($D$6&"|"&$D$7&"|"&$D$8&"|"&$D$9&"|"&9, $P$105:$P$282, 0)), 0))), IF(OR(B35="0003", B35="0011", B35="0113"), IF($D$23="NO", 0, IF(AND(ISNUMBER(K35), K35>0), ROUND(D$10/K35, 5), IFERROR(INDEX($I$105:$I$282, MATCH($D$6&"|"&$D$7&"|"&$D$8&"|"&$D$9&"|"&9, $P$105:$P$282, 0)), 0))), IF(AND(ISNUMBER(K35), K35>0), ROUND(D$10/K35, 5), IFERROR(INDEX($I$105:$I$282, MATCH($D$6&"|"&$D$7&"|"&$D$8&"|"&$D$9&"|"&9, $P$105:$P$282, 0)), 0))))) | G35: =IF(B35="","", IFERROR(INDEX(Rates_Master!$E:$E, MATCH(B35, Rates_Master!$A:$A, 0)), IFERROR(INDEX($K$105:$K$282, MATCH($D$6&"|"&$D$7&"|"&$D$8&"|"&$D$9&"|"&9, $P$105:$P$282, 0)), 0))) | H35: =IF(OR(B35="", F35=""), 0, ROUND(F35 * G35, 2)) | I35: =IF(B35="","", IF(ISNUMBER(SEARCH("2.10", B35)), "A", "W")) | J35: =IF(H$41>0, ROUND(H35 / H$41 * 100, 1), 0) | K35: =IFERROR(INDEX($N$105:$N$282, MATCH($D$6&"|"&$D$7&"|"&$D$8&"|"&$D$9&"|"&9, $P$105:$P$282, 0)), "") | L35: =IF(AND(ISNUMBER(F35), F35>0, D$10>0), ROUND(F35 * 8 / D$10, 4), "") | M35: =IF(AND(ISNUMBER(F35), F35>0, D$10>0), ROUND(D$10 / (F35 * 8), 2), "") | N35: =IF(B35="","", "CPWD Standard Earthwork Production Resource") | O35: =IF(B35="","", IF(B35="0101", IF($D$22="NO", "OMITTED DEDUCTION (DAR Item 2.5): 0.40 Bhishti-day @ Rs 617 = Rs 246.80 direct. Compounded with GST 14.05% (Rs 34.68) + CPOH 15% (Rs 42.22) + Cess 1% (Rs 3.24) = Rs 326.94/10 cum -> -Rs 33.00/cum deduction.", "Watering by Bhishti to OMC: 25 cum/8-hr day (0.40 day/10 cum)."), IF(OR(B35="0003", B35="0011", B35="0113"), IF($D$23="NO", "OMITTED DEDUCTION (DAR Item 2.4): 0.008 Roller @ Rs 3000 (Rs 24.00) + 0.008 Chowkidar (Rs 4.46) + Sundries (Rs 3.64) = Rs 32.10 direct. Compounded with Water 1% (Rs 0.32) + GST 14.05% (Rs 4.55) + CPOH 15% (Rs 5.55) + Cess 1% (Rs 0.43) = Rs 42.95/10 cum -> -Rs 4.30/cum deduction.", "Power roller compaction: 1250 cum/8-hr day (0.008 day/10 cum)."), IFERROR(INDEX($O$105:$O$282, MATCH($D$6&"|"&$D$7&"|"&$D$8&"|"&$D$9&"|"&9, $P$105:$P$282, 0)), ""))))
A36: 10 | B36: =IFERROR(INDEX($G$105:$G$282, MATCH($D$6&"|"&$D$7&"|"&$D$8&"|"&$D$9&"|"&10, $P$105:$P$282, 0)), "") | C36: =IF(B36="","", IFERROR(INDEX(Rates_Master!$C:$C, MATCH(B36, Rates_Master!$A:$A, 0)), IFERROR(INDEX($H$105:$H$282, MATCH($D$6&"|"&$D$7&"|"&$D$8&"|"&$D$9&"|"&10, $P$105:$P$282, 0)), "Custom Resource"))) | D36: =IF(B36="","", IFERROR(INDEX(Rates_Master!$B:$B, MATCH(B36, Rates_Master!$A:$A, 0)), "Labour")) | E36: =IF(B36="","", IFERROR(INDEX(Rates_Master!$D:$D, MATCH(B36, Rates_Master!$A:$A, 0)), "day")) | F36: =IF(B36="","", IF(B36="0101", IF($D$22="NO", 0, IF(AND(ISNUMBER(K36), K36>0), ROUND(D$10/K36, 5), IFERROR(INDEX($I$105:$I$282, MATCH($D$6&"|"&$D$7&"|"&$D$8&"|"&$D$9&"|"&10, $P$105:$P$282, 0)), 0))), IF(OR(B36="0003", B36="0011", B36="0113"), IF($D$23="NO", 0, IF(AND(ISNUMBER(K36), K36>0), ROUND(D$10/K36, 5), IFERROR(INDEX($I$105:$I$282, MATCH($D$6&"|"&$D$7&"|"&$D$8&"|"&$D$9&"|"&10, $P$105:$P$282, 0)), 0))), IF(AND(ISNUMBER(K36), K36>0), ROUND(D$10/K36, 5), IFERROR(INDEX($I$105:$I$282, MATCH($D$6&"|"&$D$7&"|"&$D$8&"|"&$D$9&"|"&10, $P$105:$P$282, 0)), 0))))) | G36: =IF(B36="","", IFERROR(INDEX(Rates_Master!$E:$E, MATCH(B36, Rates_Master!$A:$A, 0)), IFERROR(INDEX($K$105:$K$282, MATCH($D$6&"|"&$D$7&"|"&$D$8&"|"&$D$9&"|"&10, $P$105:$P$282, 0)), 0))) | H36: =IF(OR(B36="", F36=""), 0, ROUND(F36 * G36, 2)) | I36: =IF(B36="","", IF(ISNUMBER(SEARCH("2.10", B36)), "A", "W")) | J36: =IF(H$41>0, ROUND(H36 / H$41 * 100, 1), 0) | K36: =IFERROR(INDEX($N$105:$N$282, MATCH($D$6&"|"&$D$7&"|"&$D$8&"|"&$D$9&"|"&10, $P$105:$P$282, 0)), "") | L36: =IF(AND(ISNUMBER(F36), F36>0, D$10>0), ROUND(F36 * 8 / D$10, 4), "") | M36: =IF(AND(ISNUMBER(F36), F36>0, D$10>0), ROUND(D$10 / (F36 * 8), 2), "") | N36: =IF(B36="","", "CPWD Standard Earthwork Production Resource") | O36: =IF(B36="","", IF(B36="0101", IF($D$22="NO", "OMITTED DEDUCTION (DAR Item 2.5): 0.40 Bhishti-day @ Rs 617 = Rs 246.80 direct. Compounded with GST 14.05% (Rs 34.68) + CPOH 15% (Rs 42.22) + Cess 1% (Rs 3.24) = Rs 326.94/10 cum -> -Rs 33.00/cum deduction.", "Watering by Bhishti to OMC: 25 cum/8-hr day (0.40 day/10 cum)."), IF(OR(B36="0003", B36="0011", B36="0113"), IF($D$23="NO", "OMITTED DEDUCTION (DAR Item 2.4): 0.008 Roller @ Rs 3000 (Rs 24.00) + 0.008 Chowkidar (Rs 4.46) + Sundries (Rs 3.64) = Rs 32.10 direct. Compounded with Water 1% (Rs 0.32) + GST 14.05% (Rs 4.55) + CPOH 15% (Rs 5.55) + Cess 1% (Rs 0.43) = Rs 42.95/10 cum -> -Rs 4.30/cum deduction.", "Power roller compaction: 1250 cum/8-hr day (0.008 day/10 cum)."), IFERROR(INDEX($O$105:$O$282, MATCH($D$6&"|"&$D$7&"|"&$D$8&"|"&$D$9&"|"&10, $P$105:$P$282, 0)), ""))))
A37: 11 | B37: =IFERROR(INDEX($G$105:$G$282, MATCH($D$6&"|"&$D$7&"|"&$D$8&"|"&$D$9&"|"&11, $P$105:$P$282, 0)), "") | C37: =IF(B37="","", IFERROR(INDEX(Rates_Master!$C:$C, MATCH(B37, Rates_Master!$A:$A, 0)), IFERROR(INDEX($H$105:$H$282, MATCH($D$6&"|"&$D$7&"|"&$D$8&"|"&$D$9&"|"&11, $P$105:$P$282, 0)), "Custom Resource"))) | D37: =IF(B37="","", IFERROR(INDEX(Rates_Master!$B:$B, MATCH(B37, Rates_Master!$A:$A, 0)), "Labour")) | E37: =IF(B37="","", IFERROR(INDEX(Rates_Master!$D:$D, MATCH(B37, Rates_Master!$A:$A, 0)), "day")) | F37: =IF(B37="","", IF(B37="0101", IF($D$22="NO", 0, IF(AND(ISNUMBER(K37), K37>0), ROUND(D$10/K37, 5), IFERROR(INDEX($I$105:$I$282, MATCH($D$6&"|"&$D$7&"|"&$D$8&"|"&$D$9&"|"&11, $P$105:$P$282, 0)), 0))), IF(OR(B37="0003", B37="0011", B37="0113"), IF($D$23="NO", 0, IF(AND(ISNUMBER(K37), K37>0), ROUND(D$10/K37, 5), IFERROR(INDEX($I$105:$I$282, MATCH($D$6&"|"&$D$7&"|"&$D$8&"|"&$D$9&"|"&11, $P$105:$P$282, 0)), 0))), IF(AND(ISNUMBER(K37), K37>0), ROUND(D$10/K37, 5), IFERROR(INDEX($I$105:$I$282, MATCH($D$6&"|"&$D$7&"|"&$D$8&"|"&$D$9&"|"&11, $P$105:$P$282, 0)), 0))))) | G37: =IF(B37="","", IFERROR(INDEX(Rates_Master!$E:$E, MATCH(B37, Rates_Master!$A:$A, 0)), IFERROR(INDEX($K$105:$K$282, MATCH($D$6&"|"&$D$7&"|"&$D$8&"|"&$D$9&"|"&11, $P$105:$P$282, 0)), 0))) | H37: =IF(OR(B37="", F37=""), 0, ROUND(F37 * G37, 2)) | I37: =IF(B37="","", IF(ISNUMBER(SEARCH("2.10", B37)), "A", "W")) | J37: =IF(H$41>0, ROUND(H37 / H$41 * 100, 1), 0) | K37: =IFERROR(INDEX($N$105:$N$282, MATCH($D$6&"|"&$D$7&"|"&$D$8&"|"&$D$9&"|"&11, $P$105:$P$282, 0)), "") | L37: =IF(AND(ISNUMBER(F37), F37>0, D$10>0), ROUND(F37 * 8 / D$10, 4), "") | M37: =IF(AND(ISNUMBER(F37), F37>0, D$10>0), ROUND(D$10 / (F37 * 8), 2), "") | N37: =IF(B37="","", "CPWD Standard Earthwork Production Resource") | O37: =IF(B37="","", IF(B37="0101", IF($D$22="NO", "OMITTED DEDUCTION (DAR Item 2.5): 0.40 Bhishti-day @ Rs 617 = Rs 246.80 direct. Compounded with GST 14.05% (Rs 34.68) + CPOH 15% (Rs 42.22) + Cess 1% (Rs 3.24) = Rs 326.94/10 cum -> -Rs 33.00/cum deduction.", "Watering by Bhishti to OMC: 25 cum/8-hr day (0.40 day/10 cum)."), IF(OR(B37="0003", B37="0011", B37="0113"), IF($D$23="NO", "OMITTED DEDUCTION (DAR Item 2.4): 0.008 Roller @ Rs 3000 (Rs 24.00) + 0.008 Chowkidar (Rs 4.46) + Sundries (Rs 3.64) = Rs 32.10 direct. Compounded with Water 1% (Rs 0.32) + GST 14.05% (Rs 4.55) + CPOH 15% (Rs 5.55) + Cess 1% (Rs 0.43) = Rs 42.95/10 cum -> -Rs 4.30/cum deduction.", "Power roller compaction: 1250 cum/8-hr day (0.008 day/10 cum)."), IFERROR(INDEX($O$105:$O$282, MATCH($D$6&"|"&$D$7&"|"&$D$8&"|"&$D$9&"|"&11, $P$105:$P$282, 0)), ""))))
A38: 12 | B38: =IFERROR(INDEX($G$105:$G$282, MATCH($D$6&"|"&$D$7&"|"&$D$8&"|"&$D$9&"|"&12, $P$105:$P$282, 0)), "") | C38: =IF(B38="","", IFERROR(INDEX(Rates_Master!$C:$C, MATCH(B38, Rates_Master!$A:$A, 0)), IFERROR(INDEX($H$105:$H$282, MATCH($D$6&"|"&$D$7&"|"&$D$8&"|"&$D$9&"|"&12, $P$105:$P$282, 0)), "Custom Resource"))) | D38: =IF(B38="","", IFERROR(INDEX(Rates_Master!$B:$B, MATCH(B38, Rates_Master!$A:$A, 0)), "Labour")) | E38: =IF(B38="","", IFERROR(INDEX(Rates_Master!$D:$D, MATCH(B38, Rates_Master!$A:$A, 0)), "day")) | F38: =IF(B38="","", IF(B38="0101", IF($D$22="NO", 0, IF(AND(ISNUMBER(K38), K38>0), ROUND(D$10/K38, 5), IFERROR(INDEX($I$105:$I$282, MATCH($D$6&"|"&$D$7&"|"&$D$8&"|"&$D$9&"|"&12, $P$105:$P$282, 0)), 0))), IF(OR(B38="0003", B38="0011", B38="0113"), IF($D$23="NO", 0, IF(AND(ISNUMBER(K38), K38>0), ROUND(D$10/K38, 5), IFERROR(INDEX($I$105:$I$282, MATCH($D$6&"|"&$D$7&"|"&$D$8&"|"&$D$9&"|"&12, $P$105:$P$282, 0)), 0))), IF(AND(ISNUMBER(K38), K38>0), ROUND(D$10/K38, 5), IFERROR(INDEX($I$105:$I$282, MATCH($D$6&"|"&$D$7&"|"&$D$8&"|"&$D$9&"|"&12, $P$105:$P$282, 0)), 0))))) | G38: =IF(B38="","", IFERROR(INDEX(Rates_Master!$E:$E, MATCH(B38, Rates_Master!$A:$A, 0)), IFERROR(INDEX($K$105:$K$282, MATCH($D$6&"|"&$D$7&"|"&$D$8&"|"&$D$9&"|"&12, $P$105:$P$282, 0)), 0))) | H38: =IF(OR(B38="", F38=""), 0, ROUND(F38 * G38, 2)) | I38: =IF(B38="","", IF(ISNUMBER(SEARCH("2.10", B38)), "A", "W")) | J38: =IF(H$41>0, ROUND(H38 / H$41 * 100, 1), 0) | K38: =IFERROR(INDEX($N$105:$N$282, MATCH($D$6&"|"&$D$7&"|"&$D$8&"|"&$D$9&"|"&12, $P$105:$P$282, 0)), "") | L38: =IF(AND(ISNUMBER(F38), F38>0, D$10>0), ROUND(F38 * 8 / D$10, 4), "") | M38: =IF(AND(ISNUMBER(F38), F38>0, D$10>0), ROUND(D$10 / (F38 * 8), 2), "") | N38: =IF(B38="","", "CPWD Standard Earthwork Production Resource") | O38: =IF(B38="","", IF(B38="0101", IF($D$22="NO", "OMITTED DEDUCTION (DAR Item 2.5): 0.40 Bhishti-day @ Rs 617 = Rs 246.80 direct. Compounded with GST 14.05% (Rs 34.68) + CPOH 15% (Rs 42.22) + Cess 1% (Rs 3.24) = Rs 326.94/10 cum -> -Rs 33.00/cum deduction.", "Watering by Bhishti to OMC: 25 cum/8-hr day (0.40 day/10 cum)."), IF(OR(B38="0003", B38="0011", B38="0113"), IF($D$23="NO", "OMITTED DEDUCTION (DAR Item 2.4): 0.008 Roller @ Rs 3000 (Rs 24.00) + 0.008 Chowkidar (Rs 4.46) + Sundries (Rs 3.64) = Rs 32.10 direct. Compounded with Water 1% (Rs 0.32) + GST 14.05% (Rs 4.55) + CPOH 15% (Rs 5.55) + Cess 1% (Rs 0.43) = Rs 42.95/10 cum -> -Rs 4.30/cum deduction.", "Power roller compaction: 1250 cum/8-hr day (0.008 day/10 cum)."), IFERROR(INDEX($O$105:$O$282, MATCH($D$6&"|"&$D$7&"|"&$D$8&"|"&$D$9&"|"&12, $P$105:$P$282, 0)), ""))))
A39: 13 | B39: =IFERROR(INDEX($G$105:$G$282, MATCH($D$6&"|"&$D$7&"|"&$D$8&"|"&$D$9&"|"&13, $P$105:$P$282, 0)), "") | C39: =IF(B39="","", IFERROR(INDEX(Rates_Master!$C:$C, MATCH(B39, Rates_Master!$A:$A, 0)), IFERROR(INDEX($H$105:$H$282, MATCH($D$6&"|"&$D$7&"|"&$D$8&"|"&$D$9&"|"&13, $P$105:$P$282, 0)), "Custom Resource"))) | D39: =IF(B39="","", IFERROR(INDEX(Rates_Master!$B:$B, MATCH(B39, Rates_Master!$A:$A, 0)), "Labour")) | E39: =IF(B39="","", IFERROR(INDEX(Rates_Master!$D:$D, MATCH(B39, Rates_Master!$A:$A, 0)), "day")) | F39: =IF(B39="","", IF(B39="0101", IF($D$22="NO", 0, IF(AND(ISNUMBER(K39), K39>0), ROUND(D$10/K39, 5), IFERROR(INDEX($I$105:$I$282, MATCH($D$6&"|"&$D$7&"|"&$D$8&"|"&$D$9&"|"&13, $P$105:$P$282, 0)), 0))), IF(OR(B39="0003", B39="0011", B39="0113"), IF($D$23="NO", 0, IF(AND(ISNUMBER(K39), K39>0), ROUND(D$10/K39, 5), IFERROR(INDEX($I$105:$I$282, MATCH($D$6&"|"&$D$7&"|"&$D$8&"|"&$D$9&"|"&13, $P$105:$P$282, 0)), 0))), IF(AND(ISNUMBER(K39), K39>0), ROUND(D$10/K39, 5), IFERROR(INDEX($I$105:$I$282, MATCH($D$6&"|"&$D$7&"|"&$D$8&"|"&$D$9&"|"&13, $P$105:$P$282, 0)), 0))))) | G39: =IF(B39="","", IFERROR(INDEX(Rates_Master!$E:$E, MATCH(B39, Rates_Master!$A:$A, 0)), IFERROR(INDEX($K$105:$K$282, MATCH($D$6&"|"&$D$7&"|"&$D$8&"|"&$D$9&"|"&13, $P$105:$P$282, 0)), 0))) | H39: =IF(OR(B39="", F39=""), 0, ROUND(F39 * G39, 2)) | I39: =IF(B39="","", IF(ISNUMBER(SEARCH("2.10", B39)), "A", "W")) | J39: =IF(H$41>0, ROUND(H39 / H$41 * 100, 1), 0) | K39: =IFERROR(INDEX($N$105:$N$282, MATCH($D$6&"|"&$D$7&"|"&$D$8&"|"&$D$9&"|"&13, $P$105:$P$282, 0)), "") | L39: =IF(AND(ISNUMBER(F39), F39>0, D$10>0), ROUND(F39 * 8 / D$10, 4), "") | M39: =IF(AND(ISNUMBER(F39), F39>0, D$10>0), ROUND(D$10 / (F39 * 8), 2), "") | N39: =IF(B39="","", "CPWD Standard Earthwork Production Resource") | O39: =IF(B39="","", IF(B39="0101", IF($D$22="NO", "OMITTED DEDUCTION (DAR Item 2.5): 0.40 Bhishti-day @ Rs 617 = Rs 246.80 direct. Compounded with GST 14.05% (Rs 34.68) + CPOH 15% (Rs 42.22) + Cess 1% (Rs 3.24) = Rs 326.94/10 cum -> -Rs 33.00/cum deduction.", "Watering by Bhishti to OMC: 25 cum/8-hr day (0.40 day/10 cum)."), IF(OR(B39="0003", B39="0011", B39="0113"), IF($D$23="NO", "OMITTED DEDUCTION (DAR Item 2.4): 0.008 Roller @ Rs 3000 (Rs 24.00) + 0.008 Chowkidar (Rs 4.46) + Sundries (Rs 3.64) = Rs 32.10 direct. Compounded with Water 1% (Rs 0.32) + GST 14.05% (Rs 4.55) + CPOH 15% (Rs 5.55) + Cess 1% (Rs 0.43) = Rs 42.95/10 cum -> -Rs 4.30/cum deduction.", "Power roller compaction: 1250 cum/8-hr day (0.008 day/10 cum)."), IFERROR(INDEX($O$105:$O$282, MATCH($D$6&"|"&$D$7&"|"&$D$8&"|"&$D$9&"|"&13, $P$105:$P$282, 0)), ""))))
A40: 14 | B40: =IFERROR(INDEX($G$105:$G$282, MATCH($D$6&"|"&$D$7&"|"&$D$8&"|"&$D$9&"|"&14, $P$105:$P$282, 0)), "") | C40: =IF(B40="","", IFERROR(INDEX(Rates_Master!$C:$C, MATCH(B40, Rates_Master!$A:$A, 0)), IFERROR(INDEX($H$105:$H$282, MATCH($D$6&"|"&$D$7&"|"&$D$8&"|"&$D$9&"|"&14, $P$105:$P$282, 0)), "Custom Resource"))) | D40: =IF(B40="","", IFERROR(INDEX(Rates_Master!$B:$B, MATCH(B40, Rates_Master!$A:$A, 0)), "Labour")) | E40: =IF(B40="","", IFERROR(INDEX(Rates_Master!$D:$D, MATCH(B40, Rates_Master!$A:$A, 0)), "day")) | F40: =IF(B40="","", IF(B40="0101", IF($D$22="NO", 0, IF(AND(ISNUMBER(K40), K40>0), ROUND(D$10/K40, 5), IFERROR(INDEX($I$105:$I$282, MATCH($D$6&"|"&$D$7&"|"&$D$8&"|"&$D$9&"|"&14, $P$105:$P$282, 0)), 0))), IF(OR(B40="0003", B40="0011", B40="0113"), IF($D$23="NO", 0, IF(AND(ISNUMBER(K40), K40>0), ROUND(D$10/K40, 5), IFERROR(INDEX($I$105:$I$282, MATCH($D$6&"|"&$D$7&"|"&$D$8&"|"&$D$9&"|"&14, $P$105:$P$282, 0)), 0))), IF(AND(ISNUMBER(K40), K40>0), ROUND(D$10/K40, 5), IFERROR(INDEX($I$105:$I$282, MATCH($D$6&"|"&$D$7&"|"&$D$8&"|"&$D$9&"|"&14, $P$105:$P$282, 0)), 0))))) | G40: =IF(B40="","", IFERROR(INDEX(Rates_Master!$E:$E, MATCH(B40, Rates_Master!$A:$A, 0)), IFERROR(INDEX($K$105:$K$282, MATCH($D$6&"|"&$D$7&"|"&$D$8&"|"&$D$9&"|"&14, $P$105:$P$282, 0)), 0))) | H40: =IF(OR(B40="", F40=""), 0, ROUND(F40 * G40, 2)) | I40: =IF(B40="","", IF(ISNUMBER(SEARCH("2.10", B40)), "A", "W")) | J40: =IF(H$41>0, ROUND(H40 / H$41 * 100, 1), 0) | K40: =IFERROR(INDEX($N$105:$N$282, MATCH($D$6&"|"&$D$7&"|"&$D$8&"|"&$D$9&"|"&14, $P$105:$P$282, 0)), "") | L40: =IF(AND(ISNUMBER(F40), F40>0, D$10>0), ROUND(F40 * 8 / D$10, 4), "") | M40: =IF(AND(ISNUMBER(F40), F40>0, D$10>0), ROUND(D$10 / (F40 * 8), 2), "") | N40: =IF(B40="","", "CPWD Standard Earthwork Production Resource") | O40: =IF(B40="","", IF(B40="0101", IF($D$22="NO", "OMITTED DEDUCTION (DAR Item 2.5): 0.40 Bhishti-day @ Rs 617 = Rs 246.80 direct. Compounded with GST 14.05% (Rs 34.68) + CPOH 15% (Rs 42.22) + Cess 1% (Rs 3.24) = Rs 326.94/10 cum -> -Rs 33.00/cum deduction.", "Watering by Bhishti to OMC: 25 cum/8-hr day (0.40 day/10 cum)."), IF(OR(B40="0003", B40="0011", B40="0113"), IF($D$23="NO", "OMITTED DEDUCTION (DAR Item 2.4): 0.008 Roller @ Rs 3000 (Rs 24.00) + 0.008 Chowkidar (Rs 4.46) + Sundries (Rs 3.64) = Rs 32.10 direct. Compounded with Water 1% (Rs 0.32) + GST 14.05% (Rs 4.55) + CPOH 15% (Rs 5.55) + Cess 1% (Rs 0.43) = Rs 42.95/10 cum -> -Rs 4.30/cum deduction.", "Power roller compaction: 1250 cum/8-hr day (0.008 day/10 cum)."), IFERROR(INDEX($O$105:$O$282, MATCH($D$6&"|"&$D$7&"|"&$D$8&"|"&$D$9&"|"&14, $P$105:$P$282, 0)), ""))))
A41: Direct Production Cost W = Σ Amount (all active resource lines): | H41: 1 | I41: W | J41: Base for statutory markup calculations before exclusion of pre-marked reference items.
A42: A-tagged Total (pre-marked composite reference items excluded from markups): | H42: 1 | I42: A | J42: Uses robust SUMIF to guarantee error-free evaluation even with empty slots.
...
